Workbook
Name データリスト: #REF!
Name データリスト: #REF!
Name データリスト: #REF!
Name データリスト: #REF!
Name 懸賞金リスト: #REF!
Name 懸賞金リスト: #REF!
Name 懸賞金リスト: #REF!
Name 懸賞金リスト: #REF!
Name 所属ログ: テーブル7[]

Sheet キャラクターマスタ
A1: 登場キャラID | B1: 名前 | C1: 初登場時の年齢 | D1: 今の年齢 | E1: 初登場巻 | F1: 初登場話 | G1: 誕生日 | H1: 誕生年（海円暦） | I1: 身長 | J1: 船ID | K1: 所属船 | L1: 出身エリア | M1: 場所ID | N1: 出身島・国 | O1: 二つ名 | P1: 実ID | Q1: 悪魔の実 | R1: 勢力ID | S1: 所属 | T1: 役職 | U1: 覇気 | V1: 性別 | W1: 種族 | X1: 階級（社会的） | Y1: 死亡年 | Z1: 死亡年（海円暦） | AA1: 生存ステータス | AB1: 重要度 | AC1: Dフラグ | AD1: 登場日 | AE1: 退場日 | AF1: 武器 | AG1: 血液型 | AH1: 好物 | AI1: 嫌いな食べ物 | AJ1: 趣味 | AK1: イメージ動物 | AL1: 国 | AM1: 職業 | AN1: 花 | AO1: 好きな島 | AP1: その他
A2: C001-01 | B2: モンキー・D・ルフィ | C2: 17 | D2: =IFERROR(キャラマスタ[[#This Row],[初登場時の年齢]]+2,"") -> 19 | E2: 1 | F2: 1 | G2: 44686 | H2: =IFERROR(IF(キャラマスタ[[#This Row],[生存ステータス]]=1,1539-キャラマスタ[[#This Row],[初登場時の年齢]]+キャラマスタ[[#This Row],[死亡年]],1539-キャラマスタ[[#This Row],[初登場時の年齢]]),"") -> 1522 | I2: 172 | J2: S-001 | K2: ゴーイング・メリー号 | L2: 東の海 | M2: L-001 | N2: フーシャ村 | O2: 麦わらのルフィ | Q2: ゴムゴムの実 | R2: G-001 | S2: 麦わらの一味 | T2: 船長 | V2: 男 | W2: 人間 | X2: 海賊 | Z2: =IF(キャラマスタ[[#This Row],[生存ステータス]]=1,1539+キャラマスタ[[#This Row],[死亡年]],"") | AA2: 0 | AB2: A | AC2: 1 | AD2: -3650 | AE2: 9999 | AG2: F | AH2: 肉全般 | AI2: ある店のチェリーパイ（なんとなく） | AK2: サル | AP2: Dの一族／超新星
A3: C001-02 | B3: ゴール・D・ロジャー | C3: 53 | D3: ー | E3: 1 | F3: 1 | G3: 44196 | H3: =IFERROR(IF(キャラマスタ[[#This Row],[生存ステータス]]=1,1539-キャラマスタ[[#This Row],[初登場時の年齢]]+キャラマスタ[[#This Row],[死亡年]],1539-キャラマスタ[[#This Row],[初登場時の年齢]]),"") -> 1464 | I3: 274 | J3: S-002 | K3: オーロ・ジャクソン号 | L3: 東の海 | M3: L-021 | N3: ローグタウン | O3: 海賊王,ゴールド・ロジャー | R3: G-002 | S3: ロジャー海賊団 | T3: 船長 | V3: 男 | W3: 人間 | X3: 海賊 | Y3: -22 | Z3: =IF(キャラマスタ[[#This Row],[生存ステータス]]=1,1539+キャラマスタ[[#This Row],[死亡年]],"") -> 1517 | AA3: 1 | AB3: B | AC3: 1 | AD3: -9125 | AE3: -8000 | AF3: 刀 | AG3: S | AH3: ヒガシザメのステーキ | AI3: 薬 | AK3: クオッカワラビー | AP3: Dの一族
A4: C001-03 | B4: アンジョウ | C4: ー | E4: 1 | F4: 1 | G4: 44562 | H4: =IFERROR(IF(キャラマスタ[[#This Row],[生存ステータス]]=1,1539-キャラマスタ[[#This Row],[初登場時の年齢]]+キャラマスタ[[#This Row],[死亡年]],1539-キャラマスタ[[#This Row],[初登場時の年齢]]),"") | L4: 東の海 | V4: 男 | W4: 人間 | X4: 市民 | Z4: =IF(キャラマスタ[[#This Row],[生存ステータス]]=1,1539+キャラマスタ[[#This Row],[死亡年]],"") | AA4: - | AB4: C | AC4: 0 | AP4: ロジャーの処刑を見に来た海賊マニア
A5: C001-04 | B5: モンスター | C5: ー | D5: =IFERROR(キャラマスタ[[#This Row],[初登場時の年齢]]+2,"") | E5: 1 | F5: 1 | G5: 44865 | H5: =IFERROR(IF(キャラマスタ[[#This Row],[生存ステータス]]=1,1539-キャラマスタ[[#This Row],[初登場時の年齢]]+キャラマスタ[[#This Row],[死亡年]],1539-キャラマスタ[[#This Row],[初登場時の年齢]]),"") | J5: S-003 | K5: レッド・フォース号 | L5: 東の海 | R5: G-003 | S5: 赤髪海賊団 | T5: 音楽家 | V5: - | W5: サル | X5: 海賊 | Z5: =IF(キャラマスタ[[#This Row],[生存ステータス]]=1,1539+キャラマスタ[[#This Row],[死亡年]],"") | AA5: 0 | AB5: B | AC5: 0 | AP5: マキノの酒場に紛れ込んでいたサル
A6: C001-05 | B6: シャンクス | C6: 37 | D6: =IFERROR(キャラマスタ[[#This Row],[初登場時の年齢]]+2,"") -> 39 | E6: 1 | F6: 1 | G6: 43899 | H6: =IFERROR(IF(キャラマスタ[[#This Row],[生存ステータス]]=1,1539-キャラマスタ[[#This Row],[初登場時の年齢]]+キャラマスタ[[#This Row],[死亡年]],1539-キャラマスタ[[#This Row],[初登場時の年齢]]),"") -> 1502 | I6: 199 | J6: S-003 | K6: レッド・フォース号 | L6: 西の海 | O6: 赤髪のシャンクス | R6: G-003 | S6: 赤髪海賊団 | T6: 大頭 | V6: 男 | W6: 人間 | X6: 海賊 | Z6: =IF(キャラマスタ[[#This Row],[生存ステータス]]=1,1539+キャラマスタ[[#This Row],[死亡年]],"") | AA6: 0 | AB6: B | AC6: 0 | AD6: -9125 | AE6: 9999 | AF6: 刀 | AG6: XF | AH6: キムチ炒飯、ロブスター | AI6: ブルーベリー | AJ6: 放浪 | AK6: ライオン
A7: C001-06 | B7: ラッキー・ルウ | C7: 33 | D7: =IFERROR(キャラマスタ[[#This Row],[初登場時の年齢]]+2,"") -> 35 | E7: 1 | F7: 1 | G7: 44018 | H7: =IFERROR(IF(キャラマスタ[[#This Row],[生存ステータス]]=1,1539-キャラマスタ[[#This Row],[初登場時の年齢]]+キャラマスタ[[#This Row],[死亡年]],1539-キャラマスタ[[#This Row],[初登場時の年齢]]),"") -> 1506 | I7: 241 | J7: S-003 | K7: レッド・フォース号 | L7: 南の海 | R7: G-003 | S7: 赤髪海賊団 | T7: コック | V7: 男 | W7: 人間 | X7: 海賊 | Z7: =IF(キャラマスタ[[#This Row],[生存ステータス]]=1,1539+キャラマスタ[[#This Row],[死亡年]],"") | AA7: 0 | AB7: B | AC7: 0 | AD7: -4015 | AE7: 9999 | AG7: F | AH7: 鳥の骨付き肉（ダイエットしているつもり）
A8: C001-07 | B8: ヤソップ | C8: 45 | D8: =IFERROR(キャラマスタ[[#This Row],[初登場時の年齢]]+2,"") -> 47 | E8: 1 | F8: 1 | G8: 44045 | H8: =IFERROR(IF(キャラマスタ[[#This Row],[生存ステータス]]=1,1539-キャラマスタ[[#This Row],[初登場時の年齢]]+キャラマスタ[[#This Row],[死亡年]],1539-キャラマスタ[[#This Row],[初登場時の年齢]]),"") -> 1494 | I8: 183 | J8: S-003 | K8: レッド・フォース号 | L8: 東の海 | M8: L-010 | N8: シロップ村 | O8: 追撃者(チェイサー） | R8: G-003 | S8: 赤髪海賊団 | T8: 狙撃手 | V8: 男 | W8: 人間 | X8: 海賊 | Z8: =IF(キャラマスタ[[#This Row],[生存ステータス]]=1,1539+キャラマスタ[[#This Row],[死亡年]],"") | AA8: 0 | AB8: B | AC8: 0 | AD8: -4380 | AE8: 9999 | AF8: 銃 | AG8: S | AH8: 旬の魚
A9: C001-08 | B9: ベン・ベックマン | C9: 48 | D9: =IFERROR(キャラマスタ[[#This Row],[初登場時の年齢]]+2,"") -> 50 | E9: 1 | F9: 1 | G9: 44144 | H9: =IFERROR(IF(キャラマスタ[[#This Row],[生存ステータス]]=1,1539-キャラマスタ[[#This Row],[初登場時の年齢]]+キャラマスタ[[#This Row],[死亡年]],1539-キャラマスタ[[#This Row],[初登場時の年齢]]),"") -> 1491 | I9: 206 | J9: S-003 | K9: レッド・フォース号 | L9: 北の海 | R9: G-003 | S9: 赤髪海賊団 | T9: 副船長 | V9: 男 | W9: 人間 | X9: 海賊 | Z9: =IF(キャラマスタ[[#This Row],[生存ステータス]]=1,1539+キャラマスタ[[#This Row],[死亡年]],"") | AA9: 0 | AB9: B | AC9: 0 | AD9: -4015 | AE9: 9999 | AF9: 銃 | AG9: X | AH9: かまぼこ
A10: C001-09 | B10: ミキオイトゥー | C10: ー | D10: =IFERROR(キャラマスタ[[#This Row],[初登場時の年齢]]+2,"") | E10: 1 | F10: 1 | G10: 44646 | H10: =IFERROR(IF(キャラマスタ[[#This Row],[生存ステータス]]=1,1539-キャラマスタ[[#This Row],[初登場時の年齢]]+キャラマスタ[[#This Row],[死亡年]],1539-キャラマスタ[[#This Row],[初登場時の年齢]]),"") | L10: 東の海 | V10: 男 | W10: 人間 | X10: - | Z10: =IF(キャラマスタ[[#This Row],[生存ステータス]]=1,1539+キャラマスタ[[#This Row],[死亡年]],"") | AA10: - | AB10: C | AC10: 0
A11: C001-10 | B11: マキノ | C11: 29 | D11: =IFERROR(キャラマスタ[[#This Row],[初登場時の年齢]]+2,"") -> 31 | E11: 1 | F11: 1 | G11: 43884 | H11: =IFERROR(IF(キャラマスタ[[#This Row],[生存ステータス]]=1,1539-キャラマスタ[[#This Row],[初登場時の年齢]]+キャラマスタ[[#This Row],[死亡年]],1539-キャラマスタ[[#This Row],[初登場時の年齢]]),"") -> 1510 | I11: 166 | L11: 東の海 | M11: L-001 | N11: フーシャ村 | S11: PARTYS BAR | T11: 店主 | V11: 女 | W11: 人間 | X11: 市民 | Z11: =IF(キャラマスタ[[#This Row],[生存ステータス]]=1,1539+キャラマスタ[[#This Row],[死亡年]],"") | AA11: 0 | AB11: B | AC11: 0 | AG11: S | AH11: ジュースとケーキ（子供と一緒に楽しめるもの）
A12: C001-11 | B12: ヒグマ | C12: 46 | D12: ー | E12: 1 | F12: 1 | G12: 44153 | H12: =IFERROR(IF(キャラマスタ[[#This Row],[生存ステータス]]=1,1539-キャラマスタ[[#This Row],[初登場時の年齢]]+キャラマスタ[[#This Row],[死亡年]],1539-キャラマスタ[[#This Row],[初登場時の年齢]]),"") -> 1483 | I12: 190 | L12: 東の海 | R12: G-004 | S12: ヒグマ山賊団 | T12: 棟梁 | V12: 男 | W12: 人間 | X12: 山賊 | Y12: -10 | Z12: =IF(キャラマスタ[[#This Row],[生存ステータス]]=1,1539+キャラマスタ[[#This Row],[死亡年]],"") -> 1529 | AA12: 1 | AB12: B | AC12: 0 | AD12: -3650 | AE12: -3640 | AF12: 刀 | AG12: X | AH12: 酒、山菜、熊肉 | AP12: 56人を殺した
A13: C001-12 | B13: ギョルさん | C13: ー | D13: =IFERROR(キャラマスタ[[#This Row],[初登場時の年齢]]+2,"") | E13: 1 | F13: 1 | G13: 44627 | H13: =IFERROR(IF(キャラマスタ[[#This Row],[生存ステータス]]=1,1539-キャラマスタ[[#This Row],[初登場時の年齢]]+キャラマスタ[[#This Row],[死亡年]],1539-キャラマスタ[[#This Row],[初登場時の年齢]]),"") | L13: 東の海 | M13: L-001 | N13: フーシャ村 | S13: フーシャ村 | T13: 魚屋 | V13: 男 | W13: 人間 | X13: 市民 | Z13: =IF(キャラマスタ[[#This Row],[生存ステータス]]=1,1539+キャラマスタ[[#This Row],[死亡年]],"") | AA13: - | AB13: C | AC13: 0
A14: C001-13 | B14: チキンおばさん | C14: ー | D14: =IFERROR(キャラマスタ[[#This Row],[初登場時の年齢]]+2,"") | E14: 1 | F14: 1 | G14: 44600 | H14: =IFERROR(IF(キャラマスタ[[#This Row],[生存ステータス]]=1,1539-キャラマスタ[[#This Row],[初登場時の年齢]]+キャラマスタ[[#This Row],[死亡年]],1539-キャラマスタ[[#This Row],[初登場時の年齢]]),"") | I14: ー | L14: 東の海 | M14: L-001 | N14: フーシャ村 | S14: フーシャ村 | T14: 魚屋 | V14: 女 | W14: 人間 | X14: 市民 | Z14: =IF(キャラマスタ[[#This Row],[生存ステータス]]=1,1539+キャラマスタ[[#This Row],[死亡年]],"") | AA14: - | AB14: C | AC14: 0 | AP14: ギョルさんのパートナー
A15: C001-14 | B15: ウープ・スラップ | C15: ー | D15: =IFERROR(キャラマスタ[[#This Row],[初登場時の年齢]]+2,"") | E15: 1 | F15: 1 | G15: 44620 | H15: =IFERROR(IF(キャラマスタ[[#This Row],[生存ステータス]]=1,1539-キャラマスタ[[#This Row],[初登場時の年齢]]+キャラマスタ[[#This Row],[死亡年]],1539-キャラマスタ[[#This Row],[初登場時の年齢]]),"") | L15: 東の海 | M15: L-001 | N15: フーシャ村 | S15: フーシャ村 | T15: 村長 | V15: 男 | W15: 人間 | X15: 市民 | Z15: =IF(キャラマスタ[[#This Row],[生存ステータス]]=1,1539+キャラマスタ[[#This Row],[死亡年]],"") | AA15: 0 | AB15: B | AC15: 0
A16: C001-15 | B16: 近海の主 | C16: ー | D16: =IFERROR(キャラマスタ[[#This Row],[初登場時の年齢]]+2,"") | E16: 1 | F16: 1 | G16: 44818 | H16: =IFERROR(IF(キャラマスタ[[#This Row],[生存ステータス]]=1,1539-キャラマスタ[[#This Row],[初登場時の年齢]]+キャラマスタ[[#This Row],[死亡年]],1539-キャラマスタ[[#This Row],[初登場時の年齢]]),"") | L16: 東の海 | V16: - | W16: 海王類 | X16: - | Z16: =IF(キャラマスタ[[#This Row],[生存ステータス]]=1,1539+キャラマスタ[[#This Row],[死亡年]],"") | AA16: 2 | AB16: B | AC16: 0 | AD16: -3645 | AE16: 1
A17: C001-16 | B17: コビー | C17: 16 | D17: =IFERROR(キャラマスタ[[#This Row],[初登場時の年齢]]+2,"") -> 18 | E17: 1 | F17: 2 | G17: 43964 | H17: =IFERROR(IF(キャラマスタ[[#This Row],[生存ステータス]]=1,1539-キャラマスタ[[#This Row],[初登場時の年齢]]+キャラマスタ[[#This Row],[死亡年]],1539-キャラマスタ[[#This Row],[初登場時の年齢]]),"") -> 1523 | I17: 167 | L17: 東の海 | R17: G-006 | S17: 海軍 | T17: 見習い | V17: 男 | W17: 人間 | X17: 海兵 | Z17: =IF(キャラマスタ[[#This Row],[生存ステータス]]=1,1539+キャラマスタ[[#This Row],[死亡年]],"") | AA17: 0 | AB17: B | AC17: 0 | AD17: -730 | AE17: 9999 | AG17: F | AH17: リカが作ったおにぎり、ジャガバター | AI17: ブラックコーヒー | AJ17: 海釣り | AK17: イルカ | AP17: アルビダの船で雑用２年
A18: C001-17 | B18: アルビダ | C18: 25 | D18: =IFERROR(キャラマスタ[[#This Row],[初登場時の年齢]]+2,"") -> 27 | E18: 1 | F18: 2 | G18: 43904 | H18: =IFERROR(IF(キャラマスタ[[#This Row],[生存ステータス]]=1,1539-キャラマスタ[[#This Row],[初登場時の年齢]]+キャラマスタ[[#This Row],[死亡年]],1539-キャラマスタ[[#This Row],[初登場時の年齢]]),"") -> 1514 | I18: 198 | J18: S-004 | K18: Missラブ・ダック号 | L18: 東の海 | O18: 金棒のアルビダ | P18: F-003 | Q18: スベスベの実 | R18: G-005 | S18: アルビダ海賊団 | T18: 船長 | V18: 女 | W18: 人間 | X18: 海賊 | Z18: =IF(キャラマスタ[[#This Row],[生存ステータス]]=1,1539+キャラマスタ[[#This Row],[死亡年]],"") | AA18: 0 | AB18: B | AC18: 0 | AD18: 1.3 | AE18: 9999 | AF18: 金棒 | AG18: S | AH18: 美肌効果のあるベリーやベリー酒
A19: C001-18 | B19: ヘッポコ | C19: ー | D19: =IFERROR(キャラマスタ[[#This Row],[初登場時の年齢]]+2,"") | E19: 1 | F19: 2 | G19: 44806 | H19: =IFERROR(IF(キャラマスタ[[#This Row],[生存ステータス]]=1,1539-キャラマスタ[[#This Row],[初登場時の年齢]]+キャラマスタ[[#This Row],[死亡年]],1539-キャラマスタ[[#This Row],[初登場時の年齢]]),"") | L19: 東の海 | R19: G-005 | S19: アルビダ海賊団 | T19: 下っ端 | V19: 男 | W19: 人間 | X19: 海賊 | Z19: =IF(キャラマスタ[[#This Row],[生存ステータス]]=1,1539+キャラマスタ[[#This Row],[死亡年]],"") | AA19: - | AB19: C | AC19: 0
A20: C001-19 | B20: ペッポコ | C20: ー | D20: =IFERROR(キャラマスタ[[#This Row],[初登場時の年齢]]+2,"") | E20: 1 | F20: 2 | G20: 44806 | H20: =IFERROR(IF(キャラマスタ[[#This Row],[生存ステータス]]=1,1539-キャラマスタ[[#This Row],[初登場時の年齢]]+キャラマスタ[[#This Row],[死亡年]],1539-キャラマスタ[[#This Row],[初登場時の年齢]]),"") | L20: 東の海 | R20: G-005 | S20: アルビダ海賊団 | T20: 下っ端 | V20: 男 | W20: 人間 | X20: 海賊 | Z20: =IF(キャラマスタ[[#This Row],[生存ステータス]]=1,1539+キャラマスタ[[#This Row],[死亡年]],"") | AA20: - | AB20: C | AC20: 0
A21: C001-20 | B21: ポッポコ | C21: ー | D21: =IFERROR(キャラマスタ[[#This Row],[初登場時の年齢]]+2,"") | E21: 1 | F21: 2 | G21: 44806 | H21: =IFERROR(IF(キャラマスタ[[#This Row],[生存ステータス]]=1,1539-キャラマスタ[[#This Row],[初登場時の年齢]]+キャラマスタ[[#This Row],[死亡年]],1539-キャラマスタ[[#This Row],[初登場時の年齢]]),"") | L21: 東の海 | R21: G-005 | S21: アルビダ海賊団 | T21: 下っ端 | V21: 男 | W21: 人間 | X21: 海賊 | Z21: =IF(キャラマスタ[[#This Row],[生存ステータス]]=1,1539+キャラマスタ[[#This Row],[死亡年]],"") | AA21: - | AB21: C | AC21: 0
A22: C001-21 | B22: ロロノア・ゾロ | C22: 19 | D22: =IFERROR(キャラマスタ[[#This Row],[初登場時の年齢]]+2,"") -> 21 | E22: 1 | F22: 3 | G22: 44146 | H22: =IFERROR(IF(キャラマスタ[[#This Row],[生存ステータス]]=1,1539-キャラマスタ[[#This Row],[初登場時の年齢]]+キャラマスタ[[#This Row],[死亡年]],1539-キャラマスタ[[#This Row],[初登場時の年齢]]),"") -> 1520 | I22: 178 | J22: S-001 | K22: ゴーイング・メリー号 | L22: 東の海 | M22: L-005 | N22: シモツキ村 | O22: 海賊狩りのゾロ | R22: G-001 | S22: 麦わらの一味 | T22: 戦闘員 | V22: 男 | W22: 人間 | X22: 海賊 | Z22: =IF(キャラマスタ[[#This Row],[生存ステータス]]=1,1539+キャラマスタ[[#This Row],[死亡年]],"") | AA22: 0 | AB22: A | AC22: 0 | AD22: -4000 | AE22: 9999 | AF22: 刀 | AG22: XF | AH22: 白米、海獣の肉、酒に合う物 | AK22: サメ | AP22: 超新星
A23: C001-22 | B23: リカ | C23: ー | D23: =IFERROR(キャラマスタ[[#This Row],[初登場時の年齢]]+2,"") | E23: 1 | F23: 3 | G23: 44730 | H23: =IFERROR(IF(キャラマスタ[[#This Row],[生存ステータス]]=1,1539-キャラマスタ[[#This Row],[初登場時の年齢]]+キャラマスタ[[#This Row],[死亡年]],1539-キャラマスタ[[#This Row],[初登場時の年齢]]),"") | L23: 東の海 | M23: L-004 | N23: シェルズタウン | V23: 女 | W23: 人間 | X23: 市民 | Z23: =IF(キャラマスタ[[#This Row],[生存ステータス]]=1,1539+キャラマスタ[[#This Row],[死亡年]],"") | AA23: 0 | AB23: C | AC23: 0 | AP23: ゾロにおにぎりをあげた女の子
A24: C001-23 | B24: ヘルメッポ | C24: 20 | D24: =IFERROR(キャラマスタ[[#This Row],[初登場時の年齢]]+2,"") -> 22 | E24: 1 | F24: 3 | G24: 44028 | H24: =IFERROR(IF(キャラマスタ[[#This Row],[生存ステータス]]=1,1539-キャラマスタ[[#This Row],[初登場時の年齢]]+キャラマスタ[[#This Row],[死亡年]],1539-キャラマスタ[[#This Row],[初登場時の年齢]]),"") -> 1519 | I24: 179 | L24: 東の海 | M24: L-004 | N24: シェルズタウン | R24: G-006 | S24: 海軍 | T24: 見習い | V24: 男 | W24: 人間 | X24: 海兵 | Z24: =IF(キャラマスタ[[#This Row],[生存ステータス]]=1,1539+キャラマスタ[[#This Row],[死亡年]],"") | AA24: 0 | AB24: B | AC24: 0 | AD24: 1.5 | AE24: 9999 | AG24: S | AH24: 豪華なステーキ、キャビア
A25: C001-24 | B25: ソーロ | C25: ー | D25: =IFERROR(キャラマスタ[[#This Row],[初登場時の年齢]]+2,"") | E25: 1 | F25: 3 | G25: 44876 | H25: =IFERROR(IF(キャラマスタ[[#This Row],[生存ステータス]]=1,1539-キャラマスタ[[#This Row],[初登場時の年齢]]+キャラマスタ[[#This Row],[死亡年]],1539-キャラマスタ[[#This Row],[初登場時の年齢]]),"") | L25: 東の海 | S25: ヘルメッポの飼い狼 | V25: - | W25: 狼 | X25: - | Z25: =IF(キャラマスタ[[#This Row],[生存ステータス]]=1,1539+キャラマスタ[[#This Row],[死亡年]],"") | AA25: - | AB25: C | AC25: 0
A26: C001-25 | B26: リリカ | C26: ー | D26: =IFERROR(キャラマスタ[[#This Row],[初登場時の年齢]]+2,"") | E26: 1 | F26: 4 | G26: 44880 | H26: =IFERROR(IF(キャラマスタ[[#This Row],[生存ステータス]]=1,1539-キャラマスタ[[#This Row],[初登場時の年齢]]+キャラマスタ[[#This Row],[死亡年]],1539-キャラマスタ[[#This Row],[初登場時の年齢]]),"") | L26: 東の海 | M26: L-004 | N26: シェルズタウン | V26: 女 | W26: 人間 | X26: 市民 | Z26: =IF(キャラマスタ[[#This Row],[生存ステータス]]=1,1539+キャラマスタ[[#This Row],[死亡年]],"") | AA26: - | AB26: C | AC26: 0 | AP26: リカの母親
A27: C001-26 | B27: モーガン | C27: 42 | D27: ー | E27: 1 | F27: 4 | G27: 43934 | H27: =IFERROR(IF(キャラマスタ[[#This Row],[生存ステータス]]=1,1539-キャラマスタ[[#This Row],[初登場時の年齢]]+キャラマスタ[[#This Row],[死亡年]],1539-キャラマスタ[[#This Row],[初登場時の年齢]]),"") -> 1497 | I27: 285 | L27: 東の海 | M27: L-004 | N27: シェルズタウン | O27: 斧手のモーガン | R27: G-006 | S27: 元海軍第153支部 | T27: 大佐 | V27: 男 | W27: 人間 | X27: 元海兵 | Z27: =IF(キャラマスタ[[#This Row],[生存ステータス]]=1,1539+キャラマスタ[[#This Row],[死亡年]],"") | AA27: 0 | AB27: B | AC27: 0 | AD27: 1.5 | AE27: 9999 | AF27: 斧手 | AG27: XF | AH27: 高級な料理 | AP27: 現在消息不明
A28: C001-27 | B28: ロッカク中尉 | C28: ー | D28: =IFERROR(キャラマスタ[[#This Row],[初登場時の年齢]]+2,"") | E28: 1 | F28: 4 | G28: 44731 | H28: =IFERROR(IF(キャラマスタ[[#This Row],[生存ステータス]]=1,1539-キャラマスタ[[#This Row],[初登場時の年齢]]+キャラマスタ[[#This Row],[死亡年]],1539-キャラマスタ[[#This Row],[初登場時の年齢]]),"") | L28: 東の海 | R28: G-006 | S28: 海軍第153支部 | T28: 中尉 | V28: 男 | W28: 人間 | X28: 海兵 | Z28: =IF(キャラマスタ[[#This Row],[生存ステータス]]=1,1539+キャラマスタ[[#This Row],[死亡年]],"") | AA28: - | AB28: C | AC28: 0 | AP28: モーガンに斬られる
A29: C001-28 | B29: ウッカリー三等兵 | C29: ー | D29: =IFERROR(キャラマスタ[[#This Row],[初登場時の年齢]]+2,"") | E29: 1 | F29: 4 | G29: 44609 | H29: =IFERROR(IF(キャラマスタ[[#This Row],[生存ステータス]]=1,1539-キャラマスタ[[#This Row],[初登場時の年齢]]+キャラマスタ[[#This Row],[死亡年]],1539-キャラマスタ[[#This Row],[初登場時の年齢]]),"") | L29: 東の海 | R29: G-006 | S29: 海軍第153支部 | T29: 三等兵 | V29: 男 | W29: 人間 | X29: 海兵 | Z29: =IF(キャラマスタ[[#This Row],[生存ステータス]]=1,1539+キャラマスタ[[#This Row],[死亡年]],"") | AA29: - | AB29: C | AC29: 0 | AP29: モーガン像の腕をうっかりぶつける
A30: C001-29 | B30: くいな | C30: 11 | D30: ー | E30: 1 | F30: 5 | G30: 44091 | H30: =IFERROR(IF(キャラマスタ[[#This Row],[生存ステータス]]=1,1539-キャラマスタ[[#This Row],[初登場時の年齢]]+キャラマスタ[[#This Row],[死亡年]],1539-キャラマスタ[[#This Row],[初登場時の年齢]]),"") -> 1517 | I30: 150 | L30: 東の海 | M30: L-005 | N30: シモツキ村 | S30: 一心道場 | T30: 門下生 | V30: 女 | W30: 人間 | X30: 市民 | Y30: -11 | Z30: =IF(キャラマスタ[[#This Row],[生存ステータス]]=1,1539+キャラマスタ[[#This Row],[死亡年]],"") -> 1528 | AA30: 1 | AB30: B | AC30: 0 | AD30: -4000 | AE30: -3950 | AG30: S | AH30: 牛乳、卵焼き | AP30: ゾロとの対戦成績：2001勝0敗、霜月くいな
A31: C001-30 | B31: コウシロウ | C31: 49 | D31: =IFERROR(キャラマスタ[[#This Row],[初登場時の年齢]]+2,"") -> 51 | E31: 1 | F31: 5 | G31: 43955 | H31: =IFERROR(IF(キャラマスタ[[#This Row],[生存ステータス]]=1,1539-キャラマスタ[[#This Row],[初登場時の年齢]]+キャラマスタ[[#This Row],[死亡年]],1539-キャラマスタ[[#This Row],[初登場時の年齢]]),"") -> 1490 | I31: 184 | L31: 東の海 | S31: 一心道場 | T31: 師範 | V31: 男 | W31: 人間 | X31: 市民 | Z31: =IF(キャラマスタ[[#This Row],[生存ステータス]]=1,1539+キャラマスタ[[#This Row],[死亡年]],"") | AA31: 0 | AB31: B | AC31: 0 | AG31: S | AH31: 道場の縁側で食べるスイカ | AP31: 霜月コウシロウ
A32: C001-31 | B32: リッパー中佐 | C32: ー | D32: =IFERROR(キャラマスタ[[#This Row],[初登場時の年齢]]+2,"") | E32: 1 | F32: 7 | G32: 44725 | H32: =IFERROR(IF(キャラマスタ[[#This Row],[生存ステータス]]=1,1539-キャラマスタ[[#This Row],[初登場時の年齢]]+キャラマスタ[[#This Row],[死亡年]],1539-キャラマスタ[[#This Row],[初登場時の年齢]]),"") | L32: 東の海 | R32: G-006 | S32: 海軍第153支部 | T32: 中佐 | V32: 男 | W32: 人間 | X32: 海兵 | Z32: =IF(キャラマスタ[[#This Row],[生存ステータス]]=1,1539+キャラマスタ[[#This Row],[死亡年]],"") | AA32: - | AB32: C | AC32: 0 | AP32: モーガンの後釜
A33: C001-32 | B33: 怪鳥ピンキー | C33: ー | D33: =IFERROR(キャラマスタ[[#This Row],[初登場時の年齢]]+2,"") | E33: 1 | F33: 8 | G33: 44833 | H33: =IFERROR(IF(キャラマスタ[[#This Row],[生存ステータス]]=1,1539-キャラマスタ[[#This Row],[初登場時の年齢]]+キャラマスタ[[#This Row],[死亡年]],1539-キャラマスタ[[#This Row],[初登場時の年齢]]),"") | L33: 東の海 | S33: 鳥 | V33: - | W33: 鳥 | X33: - | Z33: =IF(キャラマスタ[[#This Row],[生存ステータス]]=1,1539+キャラマスタ[[#This Row],[死亡年]],"") | AA33: - | AB33: C | AC33: 0 | AP33: ルフィをオレンジの町まで運ぶ
A34: C001-33 | B34: 綱渡りフナンボローズ | C34: ー | D34: =IFERROR(キャラマスタ[[#This Row],[初登場時の年齢]]+2,"") | E34: 1 | F34: 8 | G34: 44617 | H34: =IFERROR(IF(キャラマスタ[[#This Row],[生存ステータス]]=1,1539-キャラマスタ[[#This Row],[初登場時の年齢]]+キャラマスタ[[#This Row],[死亡年]],1539-キャラマスタ[[#This Row],[初登場時の年齢]]),"") | L34: 東の海 | R34: G-009 | S34: バギー海賊団 | V34: 男 | W34: 人間 | X34: 海賊 | Z34: =IF(キャラマスタ[[#This Row],[生存ステータス]]=1,1539+キャラマスタ[[#This Row],[死亡年]],"") | AA34: - | AB34: C | AC34: 0 | AP34: 難破を装いゾロを襲撃した三人組
A35: C001-34 | B35: ナミ | C35: 18 | D35: =IFERROR(キャラマスタ[[#This Row],[初登場時の年齢]]+2,"") -> 20 | E35: 1 | F35: 8 | G35: 44745 | H35: =IFERROR(IF(キャラマスタ[[#This Row],[生存ステータス]]=1,1539-キャラマスタ[[#This Row],[初登場時の年齢]]+キャラマスタ[[#This Row],[死亡年]],1539-キャラマスタ[[#This Row],[初登場時の年齢]]),"") -> 1521 | I35: 169 | J35: S-001 | K35: ゴーイング・メリー号 | L35: 東の海 | M35: L-017 | N35: ココヤシ村 | R35: G-001 | S35: 麦わらの一味 | T35: 航海士 | V35: 女 | W35: 人間 | X35: 泥棒 | Z35: =IF(キャラマスタ[[#This Row],[生存ステータス]]=1,1539+キャラマスタ[[#This Row],[死亡年]],"") | AA35: 0 | AB35: A | AC35: 0 | AD35: -2920 | AE35: 9999 | AF35: 棒 | AG35: X | AH35: みかん、フルーツ全般 | AI35: オランジェット（フルーツはそのまま食べたい） | AK35: ネコ | AP35: 86/57/86(東の海)95/55/85、東の海オイコット王国で拾われる
A36: C001-35 | B36: 怪力ドミンゴス | C36: ー | D36: =IFERROR(キャラマスタ[[#This Row],[初登場時の年齢]]+2,"") | E36: 1 | F36: 8 | G36: 44611 | H36: =IFERROR(IF(キャラマスタ[[#This Row],[生存ステータス]]=1,1539-キャラマスタ[[#This Row],[初登場時の年齢]]+キャラマスタ[[#This Row],[死亡年]],1539-キャラマスタ[[#This Row],[初登場時の年齢]]),"") | L36: 東の海 | R36: G-009 | S36: バギー海賊団 | V36: 男 | W36: 人間 | X36: 海賊 | Z36: =IF(キャラマスタ[[#This Row],[生存ステータス]]=1,1539+キャラマスタ[[#This Row],[死亡年]],"") | AA36: - | AB36: C | AC36: 0 | AP36: 海図を盗んだナミを追いかけていた三人組
A37: C002-01 | B37: バギー | C37: 37 | D37: =IFERROR(キャラマスタ[[#This Row],[初登場時の年齢]]+2,"") -> 39 | E37: 2 | F37: 9 | G37: 44051 | H37: =IFERROR(IF(キャラマスタ[[#This Row],[生存ステータス]]=1,1539-キャラマスタ[[#This Row],[初登場時の年齢]]+キャラマスタ[[#This Row],[死亡年]],1539-キャラマスタ[[#This Row],[初登場時の年齢]]),"") -> 1502 | I37: 192 | J37: S-005 | K37: ビッグトップ号 | L37: 偉大なる航路 | O37: 道化のバギー | P37: F-002 | Q37: バラバラの実 | R37: G-009 | S37: バギー海賊団 | T37: 船長 | V37: 男 | W37: 人間 | X37: 海賊 | Z37: =IF(キャラマスタ[[#This Row],[生存ステータス]]=1,1539+キャラマスタ[[#This Row],[死亡年]],"") | AA37: 0 | AB37: B | AC37: 0 | AD37: -9125 | AE37: 9999 | AG37: F | AH37: ホットドック | AI37: トマト | AJ37: 宝の地図集め | AK37: パンダ | AM37: 下町の工場長 | AN37: オダマキ | AO37: 夏島の冬 | AP37: 元ロジャー海賊団見習い/元王下七武海/四皇
A38: C002-02 | B38: どーも君 | C38: ー | D38: =IFERROR(キャラマスタ[[#This Row],[初登場時の年齢]]+2,"") | E38: 2 | F38: 9 | G38: 44591 | H38: =IFERROR(IF(キャラマスタ[[#This Row],[生存ステータス]]=1,1539-キャラマスタ[[#This Row],[初登場時の年齢]]+キャラマスタ[[#This Row],[死亡年]],1539-キャラマスタ[[#This Row],[初登場時の年齢]]),"") | S38: 宇宙人 | V38: - | W38: 宇宙人 | X38: - | Z38: =IF(キャラマスタ[[#This Row],[生存ステータス]]=1,1539+キャラマスタ[[#This Row],[死亡年]],"") | AA38: - | AB38: C | AC38: 0 | AP38: ンーケ君という仲間がいる
A39: C002-03 | B39: 軽業フワーズ | C39: ー | D39: =IFERROR(キャラマスタ[[#This Row],[初登場時の年齢]]+2,"") | E39: 2 | F39: 10 | G39: 44755 | H39: =IFERROR(IF(キャラマスタ[[#This Row],[生存ステータス]]=1,1539-キャラマスタ[[#This Row],[初登場時の年齢]]+キャラマスタ[[#This Row],[死亡年]],1539-キャラマスタ[[#This Row],[初登場時の年齢]]),"") | L39: 東の海 | R39: G-009 | S39: バギー海賊団 | V39: 男 | W39: 人間 | X39: 海賊 | Z39: =IF(キャラマスタ[[#This Row],[生存ステータス]]=1,1539+キャラマスタ[[#This Row],[死亡年]],"") | AA39: - | AB39: C | AC39: 0 | AP39: 軽やかにナミを襲った四人組
A40: C002-04 | B40: モージ | C40: 27 | D40: =IFERROR(キャラマスタ[[#This Row],[初登場時の年齢]]+2,"") -> 29 | E40: 2 | F40: 12 | G40: 44105 | H40: =IFERROR(IF(キャラマスタ[[#This Row],[生存ステータス]]=1,1539-キャラマスタ[[#This Row],[初登場時の年齢]]+キャラマスタ[[#This Row],[死亡年]],1539-キャラマスタ[[#This Row],[初登場時の年齢]]),"") -> 1512 | I40: 197 | J40: S-005 | K40: ビッグトップ号 | L40: 東の海 | O40: 猛獣使いのモージ | R40: G-009 | S40: バギー海賊団 | T40: 副船長 | V40: 男 | W40: 人間 | X40: 海賊 | Z40: =IF(キャラマスタ[[#This Row],[生存ステータス]]=1,1539+キャラマスタ[[#This Row],[死亡年]],"") | AA40: 0 | AB40: B | AC40: 0 | AD40: 1.8 | AE40: 9999 | AG40: S | AH40: つけもの
...

Sheet 悪魔の実マスタ
A1: 実ID | B1: 実の名前 | C1: 系統 | D1: キャラID | E1: 能力者 | F1: 覚醒フラグ | G1: 入手巻数 | H1: 入手年 | I1: 手放した理由
A2: F-001 | B2: ゴムゴムの実 | C2: 超人系 | D2: C001-01 | E2: =VLOOKUP(D2,キャラマスタ[],2,FALSE) -> モンキー・D・ルフィ | F2: 0 | G2: 1 | H2: -10
A3: F-002 | B3: バラバラの実 | C3: 超人系 | D3: C002-01 | E3: =VLOOKUP(D3,キャラマスタ[],2,FALSE) -> バギー | F3: 0 | G3: 2 | H3: -25
A4: F-003 | B4: スベスベの実 | C4: 超人系 | D4: C001-17 | E4: =VLOOKUP(D4,キャラマスタ[],2,FALSE) -> アルビダ | F4: 0 | G4: 11 | H4: 0
A5: F-004 | B5: モクモクの実 | C5: 自然系 | D5: C011-13 | E5: =VLOOKUP(D5,キャラマスタ[],2,FALSE) -> スモーカー | F5: 0 | G5: 11 | H5: 0
A6: F-005 | B6: ボムボムの実 | C6: 超人系 | D6: C013-02 | E6: =VLOOKUP(D6,キャラマスタ[],2,FALSE) -> Mr.5 | F6: 0 | G6: 13 | H6: 0
A7: F-006 | B7: キロキロの実 | C7: 超人系 | D7: C013-03 | E7: =VLOOKUP(D7,キャラマスタ[],2,FALSE) -> ミス・バレンタイン | F7: 0 | G7: 13 | H7: 0
A8: F-007 | B8: ハナハナの実 | C8: 超人系 | D8: C013-05 | E8: =VLOOKUP(D8,キャラマスタ[],2,FALSE) -> ミス・オールサンデー | F8: 0 | G8: 13 | H8: 0
A9: F-008 | B9: ドルドルの実 | C9: 超人系 | D9: C013-11 | E9: =VLOOKUP(D9,キャラマスタ[],2,FALSE) -> Mr.3 | F9: 0 | G9: 13 | H9: 0
A10: F-009 | E10: =VLOOKUP(D10,キャラマスタ[],2,FALSE) -> #N/A
A11: F-010 | E11: =VLOOKUP(D11,キャラマスタ[],2,FALSE) -> #N/A

Sheet 刀・武器マスタ
A1: 武器ID | B1: 武器名 | C1: 位列 | D1: 所有者ID | E1: 所有者 | F1: 製作者ID | G1: 製作者
A2: W-001 | B2: 和道一文字 | C2: 大業物 | D2: C001-21 | E2: =+IFERROR(VLOOKUP(D2,キャラマスタ[],2,FALSE),"") -> ロロノア・ゾロ | G2: 霜月コウ三郎
A3: W-002 | B3: 銀河パチンコ | D3: C003-03 | E3: =+IFERROR(VLOOKUP(D3,キャラマスタ[],2,FALSE),"") -> ウソップ
A4: W-003 | B4: 猫の手 | D4: C003-08 | E4: =+IFERROR(VLOOKUP(D4,キャラマスタ[],2,FALSE),"") -> クロ
A5: W-004 | B5: チャクラム | D5: C003-12 | E5: =+IFERROR(VLOOKUP(D5,キャラマスタ[],2,FALSE),"") -> ジャンゴ
A6: W-005 | B6: 菜斬り刀 | D6: C005-04 | E6: =+IFERROR(VLOOKUP(D6,キャラマスタ[],2,FALSE),"") -> ヨサク
A7: W-006 | B7: 夜 | C7: 最上大業物 | D7: C006-04 | E7: =+IFERROR(VLOOKUP(D7,キャラマスタ[],2,FALSE),"") -> ジュラキュール・ミホーク
A8: W-007 | B8: キリバチ | D8: C008-05 | E8: =+IFERROR(VLOOKUP(D8,キャラマスタ[],2,FALSE),"") -> アーロン
A9: W-008 | B9: 三代鬼徹 | C9: 業物 | D9: C001-21 | E9: =+IFERROR(VLOOKUP(D9,キャラマスタ[],2,FALSE),"") -> ロロノア・ゾロ | G9: 天狗山飛徹
A10: W-009 | B10: 雪走 | C10: 良業物 | D10: C001-21 | E10: =+IFERROR(VLOOKUP(D10,キャラマスタ[],2,FALSE),"") -> ロロノア・ゾロ
A11: W-010 | B11: 時雨 | C11: 業物 | D11: C011-15 | E11: =+IFERROR(VLOOKUP(D11,キャラマスタ[],2,FALSE),"") -> たしぎ
A12: W-011 | B12: フリントロック式44口径6連発リボルバー | D12: C013-02 | E12: =+IFERROR(VLOOKUP(D12,キャラマスタ[],2,FALSE),"") -> Mr.5
A13: W-012 | B13: 戦斧ブルーザーアックス | D13: C013-08 | E13: =+IFERROR(VLOOKUP(D13,キャラマスタ[],2,FALSE),"") -> ブロギー
A14: W-013 | B14: 巨剣テリーソード | D14: C013-09 | E14: =+IFERROR(VLOOKUP(D14,キャラマスタ[],2,FALSE),"") -> ドリー
A15: W-014 | E15: =+IFERROR(VLOOKUP(D15,キャラマスタ[],2,FALSE),"")
A16: W-015 | E16: =+IFERROR(VLOOKUP(D16,キャラマスタ[],2,FALSE),"")
A17: W-016 | E17: =+IFERROR(VLOOKUP(D17,キャラマスタ[],2,FALSE),"")
A18: W-017 | E18: =+IFERROR(VLOOKUP(D18,キャラマスタ[],2,FALSE),"")
A19: W-018 | E19: =+IFERROR(VLOOKUP(D19,キャラマスタ[],2,FALSE),"")
A20: W-019 | E20: =+IFERROR(VLOOKUP(D20,キャラマスタ[],2,FALSE),"")
A21: W-020 | E21: =+IFERROR(VLOOKUP(D21,キャラマスタ[],2,FALSE),"")

Sheet 船マスタ
A1: 船ID | B1: 船名 | C1: 持ち主 | D1: 造船者 | E1: 材質 | F1: 状態
A2: S-001 | B2: ゴーイング・メリー号 | C2: モンキー・D・ルフィ
A3: S-002 | B3: オーロ・ジャクソン号 | C3: ゴール・D・ロジャー
A4: S-003 | B4: レッド・フォース号 | C4: シャンクス
A5: S-004 | B5: Missラブ・ダック号 | C5: アルビダ
A6: S-005 | B6: ビッグトップ号 | C6: バギー
A7: S-006 | B7: マチナ・ハレルヤ号
A8: S-007 | B8: べザン・ブラック号 | C8: ジャンゴ
A9: S-008 | B9: バウンティ丸
A10: S-009 | B10: バラティエ | C10: ゼフ
A11: S-010 | B11: クッキング・ジョージ号 | C11: ゼフ
A12: S-011 | B12: ドレッドノート・サーベル号 | C12: クリーク
A13: S-012 | B13: 棺船 | C13: ジュラキュール・ミホーク
A14: S-013 | B14: 客船オービット号
A15: S-014 | B15: シャーク・スパーブ号
A16: S-015 | B16: ガープの軍艦 | C16: モンキー・D・ガープ
A17: S-016 | B17: ヴィント・グランマ号 | C17: モンキー・D・ドラゴン
A18: S-017 | B18: ポップロックキャンディ号 | C18: Mr.5
A19: S-018 | B19: グレート・エイリーク号
A20: S-019 | B20: 智略天然丸 | C20: Mr.3
A21: S-020

Sheet 場所マスタ
A1: 場所ID | B1: 地域 | C1: 島名・海域 | D1: 国名 | E1: 地名 | F1: 表示名 | G1: エリアID | H1: X | I1: Y
A2: L-001 | B2: 東の海 | C2: ドーン島 | D2: ゴア王国 | E2: フーシャ村 | F2: フーシャ村 | H2: =+テーブル13[[#This Row],[X座標]] -> 682 | I2: =+テーブル13[[#This Row],[Y座標]] -> 390.5
A3: L-002 | B3: 東の海 | C3: ドーン島 | D3: ゴア王国 | E3: フーシャ村近海 | F3: フーシャ村近海 | H3: =+テーブル13[[#This Row],[X座標]] -> 679.5 | I3: =+テーブル13[[#This Row],[Y座標]] -> 380
A4: L-003 | B4: 東の海 | C4: ゴート島 | D4: （不明） | E4: （不明） | F4: ゴート島 | H4: =+テーブル13[[#This Row],[X座標]] -> 632.5 | I4: =+テーブル13[[#This Row],[Y座標]] -> 379.5
A5: L-004 | B5: 東の海 | C5: ヨツバ島海域 | D5: （不明） | E5: シェルズタウン | F5: シェルズタウン | H5: =+テーブル13[[#This Row],[X座標]] -> 647.5 | I5: =+テーブル13[[#This Row],[Y座標]] -> 425.5
A6: L-005 | B6: 東の海 | C6: （不明） | D6: （不明） | E6: シモツキ村 | F6: シモツキ村 | H6: =+テーブル13[[#This Row],[X座標]] -> 694.5 | I6: =+テーブル13[[#This Row],[Y座標]] -> 410.5
A7: L-006 | B7: 東の海 | C7: オルガン諸島 | D7: （不明） | E7: オレンジの町 | F7: オレンジの町 | H7: =+テーブル13[[#This Row],[X座標]] -> 545 | I7: =+テーブル13[[#This Row],[Y座標]] -> 342.5
A8: L-007 | B8: 不明 | C8: 不明 | D8: 不明 | E8: 不明 | F8: 不明 | H8: =+テーブル13[[#This Row],[X座標]] -> 71 | I8: =+テーブル13[[#This Row],[Y座標]] -> 428
A9: L-008 | B9: 東の海 | C9: ヨツバ島海域 | D9: （不明） | E9: シェルズタウン近海 | F9: シェルズタウン近海 | H9: =+テーブル13[[#This Row],[X座標]] -> 647.5 | I9: =+テーブル13[[#This Row],[Y座標]] -> 407
A10: L-009 | B10: 東の海 | C10: 珍獣島 | D10: （不明） | E10: （不明） | F10: 珍獣島 | H10: =+テーブル13[[#This Row],[X座標]] -> 487 | I10: =+テーブル13[[#This Row],[Y座標]] -> 319.5
A11: L-010 | B11: 東の海 | C11: ゲッコー諸島 | D11: （不明） | E11: シロップ村 | F11: シロップ村 | H11: =+テーブル13[[#This Row],[X座標]] -> 425 | I11: =+テーブル13[[#This Row],[Y座標]] -> 281
A12: L-011 | B12: 東の海 | C12: オルガン諸島 | D12: （不明） | E12: オレンジの町近海 | F12: オレンジの町近海 | H12: =+テーブル13[[#This Row],[X座標]] -> 566.5 | I12: =+テーブル13[[#This Row],[Y座標]] -> 329
A13: L-012 | B13: 東の海 | C13: ゲッコー諸島 | D13: （不明） | E13: シロップ村近海 | F13: シロップ村近海 | H13: =+テーブル13[[#This Row],[X座標]] -> 406.5 | I13: =+テーブル13[[#This Row],[Y座標]] -> 263.5
... A30: L-029 | B30: 偉大なる航路 | C30: （不明） | D30: （不明） | E30: マリンフォード | F30: 海軍本部 | H30: =+テーブル13[[#This Row],[X座標]] -> 684.5 | I30: =+テーブル13[[#This Row],[Y座標]] -> 12.5
A31: L-030

Sheet 技マスタ
A1: 技ID | B1: 技名 | C1: 使用者ID | D1: 使用者 | E1: 系統 | F1: ルーツID | G1: 初出巻数 | H1: 初出話数 | I1: 通算日 | J1: 決め技カウント | K1: 使用回数
A2: M-001 | B2: ゴムゴムの銃（ピストル） | C2: C001-01 | D2: =VLOOKUP(C2,キャラマスタ[],2,FALSE) -> モンキー・D・ルフィ | E2: 打撃 | F2: F-001 | G2: 1 | H2: 1 | I2: 1 | J2: =+SUMIF(技ログ!C:C,A2,技ログ!I:I) -> 3 | K2: =+COUNTIF(技ログ!C:C,技マスタ[[#This Row],[技ID]]) -> 8
A3: M-002 | B3: ゴムゴムのロケット | C3: C001-01 | D3: =VLOOKUP(C3,キャラマスタ[],2,FALSE) -> モンキー・D・ルフィ | E3: 移動 | F3: F-001 | G3: 1 | H3: 4 | I3: 1.3 | J3: =+SUMIF(技ログ!C:C,A3,技ログ!I:I) -> 0 | K3: =+COUNTIF(技ログ!C:C,技マスタ[[#This Row],[技ID]]) -> 3
A4: M-003 | B4: ゴムゴムの鞭（ムチ） | C4: C001-01 | D4: =VLOOKUP(C4,キャラマスタ[],2,FALSE) -> モンキー・D・ルフィ | E4: 打撃 | F4: F-001 | G4: 1 | H4: 6 | I4: 1.4 | J4: =+SUMIF(技ログ!C:C,A4,技ログ!I:I) -> 0 | K4: =+COUNTIF(技ログ!C:C,技マスタ[[#This Row],[技ID]]) -> 3
A5: M-004 | B5: 特製バギー玉 | C5: C002-01 | D5: =VLOOKUP(C5,キャラマスタ[],2,FALSE) -> バギー | E5: 射撃 | F5: F-002 | G5: 2 | H5: 10 | I5: 1.8 | J5: =+SUMIF(技ログ!C:C,A5,技ログ!I:I) -> 0 | K5: =+COUNTIF(技ログ!C:C,技マスタ[[#This Row],[技ID]]) -> 3
A6: M-005 | B6: バラバラ砲 | C6: C002-01 | D6: =VLOOKUP(C6,キャラマスタ[],2,FALSE) -> バギー | E6: 特殊 | F6: F-002 | G6: 2 | H6: 11 | I6: 1.8 | J6: =+SUMIF(技ログ!C:C,A6,技ログ!I:I) -> 0 | K6: =+COUNTIF(技ログ!C:C,技マスタ[[#This Row],[技ID]]) -> 1
A7: M-006 | B7: ゴムゴムの槌（ツチ） | C7: C001-01 | D7: =VLOOKUP(C7,キャラマスタ[],2,FALSE) -> モンキー・D・ルフィ | E7: 打撃 | F7: F-001 | G7: 2 | H7: 13 | I7: 1.8 | J7: =+SUMIF(技ログ!C:C,A7,技ログ!I:I) -> 1 | K7: =+COUNTIF(技ログ!C:C,技マスタ[[#This Row],[技ID]]) -> 1
A8: M-007 | B8: ゴムゴムの風船 | C8: C001-01 | D8: =VLOOKUP(C8,キャラマスタ[],2,FALSE) -> モンキー・D・ルフィ | E8: 特殊 | F8: F-001 | G8: 2 | H8: 15 | I8: 1.8 | J8: =+SUMIF(技ログ!C:C,A8,技ログ!I:I) -> 0 | K8: =+COUNTIF(技ログ!C:C,技マスタ[[#This Row],[技ID]]) -> 3
A9: M-008 | B9: 曲技”火事おやじ” | C9: C002-10 | D9: =VLOOKUP(C9,キャラマスタ[],2,FALSE) -> カバジ | E9: 特殊 | G9: 2 | H9: 16 | I9: 1.8 | J9: =+SUMIF(技ログ!C:C,A9,技ログ!I:I) -> 0 | K9: =+COUNTIF(技ログ!C:C,技マスタ[[#This Row],[技ID]]) -> 1
A10: M-009 | B10: 曲技”湯けむり殺人事件” | C10: C002-10 | D10: =VLOOKUP(C10,キャラマスタ[],2,FALSE) -> カバジ | E10: 特殊 | G10: 2 | H10: 16 | I10: 1.8 | J10: =+SUMIF(技ログ!C:C,A10,技ログ!I:I) -> 0 | K10: =+COUNTIF(技ログ!C:C,技マスタ[[#This Row],[技ID]]) -> 1
A11: M-010 | B11: 曲技”カミカゼ百コマ劇場” | C11: C002-10 | D11: =VLOOKUP(C11,キャラマスタ[],2,FALSE) -> カバジ | E11: 特殊 | G11: 2 | H11: 17 | I11: 1.8 | J11: =+SUMIF(技ログ!C:C,A11,技ログ!I:I) -> 0 | K11: =+COUNTIF(技ログ!C:C,技マスタ[[#This Row],[技ID]]) -> 1
A12: M-011 | B12: 曲技”山登ろー” | C12: C002-10 | D12: =VLOOKUP(C12,キャラマスタ[],2,FALSE) -> カバジ | E12: 特殊 | G12: 2 | H12: 17 | I12: 1.8 | J12: =+SUMIF(技ログ!C:C,A12,技ログ!I:I) -> 0 | K12: =+COUNTIF(技ログ!C:C,技マスタ[[#This Row],[技ID]]) -> 1
A13: M-012 | B13: 曲技”納涼打ち上げ花火” | C13: C002-10 | D13: =VLOOKUP(C13,キャラマスタ[],2,FALSE) -> カバジ | E13: 特殊 | G13: 2 | H13: 17 | I13: 1.8 | J13: =+SUMIF(技ログ!C:C,A13,技ログ!I:I) -> 0 | K13: =+COUNTIF(技ログ!C:C,技マスタ[[#This Row],[技ID]]) -> 1
A14: M-013 | B14: ”一輪刺し” | C14: C002-10 | D14: =VLOOKUP(C14,キャラマスタ[],2,FALSE) -> カバジ | E14: 斬撃 | G14: 2 | H14: 17 | I14: 1.8 | J14: =+SUMIF(技ログ!C:C,A14,技ログ!I:I) -> 0 | K14: =+COUNTIF(技ログ!C:C,技マスタ[[#This Row],[技ID]]) -> 1
A15: M-014 | B15: 地をはう”バラバラ砲” | C15: C002-01 | D15: =VLOOKUP(C15,キャラマスタ[],2,FALSE) -> バギー | E15: 射撃 | F15: F-002 | G15: 2 | H15: 17 | I15: 1.8 | J15: =+SUMIF(技ログ!C:C,A15,技ログ!I:I) -> 0 | K15: =+COUNTIF(技ログ!C:C,技マスタ[[#This Row],[技ID]]) -> 1
A16: M-015 | B16: 鬼斬り | C16: C001-21 | D16: =VLOOKUP(C16,キャラマスタ[],2,FALSE) -> ロロノア・ゾロ | E16: 斬撃 | G16: 2 | H16: 17 | I16: 1.8 | J16: =+SUMIF(技ログ!C:C,A16,技ログ!I:I) -> 1 | K16: =+COUNTIF(技ログ!C:C,技マスタ[[#This Row],[技ID]]) -> 4
A17: M-016 | B17: バラバラせんべい | C17: C002-01 | D17: =VLOOKUP(C17,キャラマスタ[],2,FALSE) -> バギー | E17: 斬撃 | F17: F-002 | G17: 3 | H17: 18 | I17: 1.8 | J17: =+SUMIF(技ログ!C:C,A17,技ログ!I:I) -> 0 | K17: =+COUNTIF(技ログ!C:C,技マスタ[[#This Row],[技ID]]) -> 1
A18: M-017 | B18: バラバラ緊急脱出 | C18: C002-01 | D18: =VLOOKUP(C18,キャラマスタ[],2,FALSE) -> バギー | E18: 特殊 | F18: F-002 | G18: 3 | H18: 18 | I18: 1.8 | J18: =+SUMIF(技ログ!C:C,A18,技ログ!I:I) -> 0 | K18: =+COUNTIF(技ログ!C:C,技マスタ[[#This Row],[技ID]]) -> 2
A19: M-018 | B19: ゴムゴムの鎌 | C19: C001-01 | D19: =VLOOKUP(C19,キャラマスタ[],2,FALSE) -> モンキー・D・ルフィ | E19: 打撃 | F19: F-001 | G19: 3 | H19: 18 | I19: 1.8 | J19: =+SUMIF(技ログ!C:C,A19,技ログ!I:I) -> 0 | K19: =+COUNTIF(技ログ!C:C,技マスタ[[#This Row],[技ID]]) -> 1
A20: M-019 | B20: バラバラ砲・切り離し | C20: C002-01 | D20: =VLOOKUP(C20,キャラマスタ[],2,FALSE) -> バギー | E20: 斬撃 | F20: F-002 | G20: 3 | H20: 18 | I20: 1.8 | J20: =+SUMIF(技ログ!C:C,A20,技ログ!I:I) -> 0 | K20: =+COUNTIF(技ログ!C:C,技マスタ[[#This Row],[技ID]]) -> 1
A21: M-020 | B21: バラバラフェスティバル | C21: C002-01 | D21: =VLOOKUP(C21,キャラマスタ[],2,FALSE) -> バギー | E21: 特殊 | F21: F-002 | G21: 3 | H21: 20 | I21: 1.8 | J21: =+SUMIF(技ログ!C:C,A21,技ログ!I:I) -> 0 | K21: =+COUNTIF(技ログ!C:C,技マスタ[[#This Row],[技ID]]) -> 2
A22: M-021 | B22: ゴムゴムのバズーカ | C22: C001-01 | D22: =VLOOKUP(C22,キャラマスタ[],2,FALSE) -> モンキー・D・ルフィ | E22: 打撃 | F22: F-001 | G22: 3 | H22: 20 | I22: 1.8 | J22: =+SUMIF(技ログ!C:C,A22,技ログ!I:I) -> 1 | K22: =+COUNTIF(技ログ!C:C,技マスタ[[#This Row],[技ID]]) -> 5
A23: M-022 | B23: ワン・ツー・ジャンゴ | C23: C003-12 | D23: =VLOOKUP(C23,キャラマスタ[],2,FALSE) -> ジャンゴ | E23: 特殊 | G23: 3 | H23: 25 | I23: 2.5 | J23: =+SUMIF(技ログ!C:C,A23,技ログ!I:I) -> 0 | K23: =+COUNTIF(技ログ!C:C,技マスタ[[#This Row],[技ID]]) -> 6
A24: M-023 | B24: まきびし地獄 | C24: C003-03 | D24: =VLOOKUP(C24,キャラマスタ[],2,FALSE) -> ウソップ | E24: 特殊 | G24: 4 | H24: 29 | I24: 3 | J24: =+SUMIF(技ログ!C:C,A24,技ログ!I:I) -> 0 | K24: =+COUNTIF(技ログ!C:C,技マスタ[[#This Row],[技ID]]) -> 2
A25: M-024 | B25: 鉛星 | C25: C003-03 | D25: =VLOOKUP(C25,キャラマスタ[],2,FALSE) -> ウソップ | E25: 射撃 | G25: 4 | H25: 29 | I25: 3 | J25: =+SUMIF(技ログ!C:C,A25,技ログ!I:I) -> 0 | K25: =+COUNTIF(技ログ!C:C,技マスタ[[#This Row],[技ID]]) -> 4
A26: M-025 | B26: ゴムゴムの銃乱打（ガトリング） | C26: C001-01 | D26: =VLOOKUP(C26,キャラマスタ[],2,FALSE) -> モンキー・D・ルフィ | E26: 打撃 | F26: F-001 | G26: 4 | H26: 30 | I26: 3 | J26: =+SUMIF(技ログ!C:C,A26,技ログ!I:I) -> 0 | K26: =+COUNTIF(技ログ!C:C,技マスタ[[#This Row],[技ID]]) -> 3
A27: M-026 | B27: ネコババ | C27: C004-01 | D27: =VLOOKUP(C27,キャラマスタ[],2,FALSE) -> シャム | E27: 特殊 | G27: 4 | H27: 32 | I27: 3 | J27: =+SUMIF(技ログ!C:C,A27,技ログ!I:I) -> 0 | K27: =+COUNTIF(技ログ!C:C,技マスタ[[#This Row],[技ID]]) -> 1
A28: M-027 | B28: 猫殺 キャット・ザ・フンジャッタ | C28: C004-02 | D28: =VLOOKUP(C28,キャラマスタ[],2,FALSE) -> ブチ | E28: 打撃 | G28: 4 | H28: 32 | I28: 3 | J28: =+SUMIF(技ログ!C:C,A28,技ログ!I:I) -> 0 | K28: =+COUNTIF(技ログ!C:C,技マスタ[[#This Row],[技ID]]) -> 2
A29: M-028 | B29: ネコ柳大行進 | C29: C004-01 | D29: =VLOOKUP(C29,キャラマスタ[],2,FALSE) -> シャム | E29: 斬撃 | G29: 4 | H29: 32 | I29: 3 | J29: =+SUMIF(技ログ!C:C,A29,技ログ!I:I) -> 0 | K29: =+COUNTIF(技ログ!C:C,技マスタ[[#This Row],[技ID]]) -> 2
A30: M-029 | B30: 抜き足 | C30: C003-08 | D30: =VLOOKUP(C30,キャラマスタ[],2,FALSE) -> クロ | E30: 特殊 | G30: 4 | H30: 33 | I30: 3 | J30: =+SUMIF(技ログ!C:C,A30,技ログ!I:I) -> 0 | K30: =+COUNTIF(技ログ!C:C,技マスタ[[#This Row],[技ID]]) -> 2
A31: M-030 | B31: 虎狩り | C31: C001-21 | D31: =VLOOKUP(C31,キャラマスタ[],2,FALSE) -> ロロノア・ゾロ | E31: 斬撃 | G31: 4 | H31: 33 | I31: 3 | J31: =+SUMIF(技ログ!C:C,A31,技ログ!I:I) -> 1 | K31: =+COUNTIF(技ログ!C:C,技マスタ[[#This Row],[技ID]]) -> 3
A32: M-031 | B32: ゴムゴムの槍（ヤリ） | C32: C001-01 | D32: =VLOOKUP(C32,キャラマスタ[],2,FALSE) -> モンキー・D・ルフィ | E32: 打撃 | F32: F-001 | G32: 5 | H32: 36 | I32: 3 | J32: =+SUMIF(技ログ!C:C,A32,技ログ!I:I) -> 0 | K32: =+COUNTIF(技ログ!C:C,技マスタ[[#This Row],[技ID]]) -> 1
A33: M-032 | B33: コショー目つぶし | C33: C003-07 | D33: =VLOOKUP(C33,キャラマスタ[],2,FALSE) -> たまねぎ | E33: 特殊 | G33: 5 | H33: 38 | I33: 3 | J33: =+SUMIF(技ログ!C:C,A33,技ログ!I:I) -> 0 | K33: =+COUNTIF(技ログ!C:C,技マスタ[[#This Row],[技ID]]) -> 1
A34: M-033 | B34: 杓死 | C34: C003-08 | D34: =VLOOKUP(C34,キャラマスタ[],2,FALSE) -> クロ | E34: 斬撃 | G34: 5 | H34: 38 | I34: 3 | J34: =+SUMIF(技ログ!C:C,A34,技ログ!I:I) -> 0 | K34: =+COUNTIF(技ログ!C:C,技マスタ[[#This Row],[技ID]]) -> 1
A35: M-034 | B35: 火薬星 | C35: C003-03 | D35: =VLOOKUP(C35,キャラマスタ[],2,FALSE) -> ウソップ | E35: 射撃 | G35: 5 | H35: 39 | I35: 3 | J35: =+SUMIF(技ログ!C:C,A35,技ログ!I:I) -> 1 | K35: =+COUNTIF(技ログ!C:C,技マスタ[[#This Row],[技ID]]) -> 2
A36: M-035 | B36: ゴムゴムの鐘（カネ） | C36: C001-01 | D36: =VLOOKUP(C36,キャラマスタ[],2,FALSE) -> モンキー・D・ルフィ | E36: 打撃 | F36: F-001 | G36: 5 | H36: 39 | I36: 3 | J36: =+SUMIF(技ログ!C:C,A36,技ログ!I:I) -> 1 | K36: =+COUNTIF(技ログ!C:C,技マスタ[[#This Row],[技ID]]) -> 2
A37: M-036 | B37: 料理長義足キック | C37: C005-10 | D37: =VLOOKUP(C37,キャラマスタ[],2,FALSE) -> ゼフ | E37: 打撃 | G37: 5 | H37: 44 | I37: 5 | J37: =+SUMIF(技ログ!C:C,A37,技ログ!I:I) -> 0 | K37: =+COUNTIF(技ログ!C:C,技マスタ[[#This Row],[技ID]]) -> 1
A38: M-037 | B38: 料理長ドロップ | C38: C005-10 | D38: =VLOOKUP(C38,キャラマスタ[],2,FALSE) -> ゼフ | E38: 打撃 | G38: 5 | H38: 44 | I38: 5 | J38: =+SUMIF(技ログ!C:C,A38,技ログ!I:I) -> 0 | K38: =+COUNTIF(技ログ!C:C,技マスタ[[#This Row],[技ID]]) -> 1
A39: M-038 | B39: 食あたり砲弾（ミートボール） | C39: C005-12 | D39: =VLOOKUP(C39,キャラマスタ[],2,FALSE) -> パティ | E39: 射撃 | G39: 6 | H39: 47 | I39: 7 | J39: =+SUMIF(技ログ!C:C,A39,技ログ!I:I) -> 0 | K39: =+COUNTIF(技ログ!C:C,技マスタ[[#This Row],[技ID]]) -> 1
A40: M-039 | B40: 三刀流奥義 三・千・世・界 | C40: C001-21 | D40: =VLOOKUP(C40,キャラマスタ[],2,FALSE) -> ロロノア・ゾロ | E40: 斬撃 | G40: 6 | H40: 51 | I40: 7 | J40: =+SUMIF(技ログ!C:C,A40,技ログ!I:I) -> 0 | K40: =+COUNTIF(技ログ!C:C,技マスタ[[#This Row],[技ID]]) -> 1
...

Sheet 勢力マスタ
A1: 勢力ID | B1: 勢力名 | C1: リーダーID | D1: 区分
A2: G-001 | B2: 麦わらの一味 | C2: C001-01 | D2: 海賊
A3: G-002 | B3: ロジャー海賊団 | C3: C001-02 | D3: 海賊
A4: G-003 | B4: 赤髪海賊団 | C4: C001-05 | D4: 海賊
A5: G-004 | B5: ヒグマ山賊団 | C5: C001-11 | D5: 山賊
A6: G-005 | B6: アルビダ海賊団 | C6: C001-17 | D6: 海賊
A7: G-006 | B7: 海軍 | D7: 世界政府
A8: G-007 | B8: 賞金稼ぎ | D8: 賞金稼ぎ
A9: G-008 | B9: 無所属 | D9: 無所属
A10: G-009 | B10: バギー海賊団 | C10: C002-01 | D10: 海賊
A11: G-010 | B11: ウソップ海賊団 | C11: C003-03 | D11: 市民
A12: G-011 | B12: クロネコ海賊団 | C12: C003-12 | D12: 海賊
A13: G-012 | B13: 海上レストランバラティエ | C13: C005-10 | D13: 市民
A14: G-013 | B14: クリーク海賊団 | C14: C006-03 | D14: 海賊
A15: G-014 | B15: 王下七武海 | D15: 世界政府
A16: G-015 | B16: クック海賊団 | C16: C005-10 | D16: 海賊
A17: G-016 | B17: 客船 | D17: 市民
A18: G-017 | B18: アーロン一味 | C18: C008-05 | D18: 海賊
A19: G-018 | B19: 革命軍 | C19: C012-01 | D19: 革命軍
A20: G-019 | B20: バロック・ワークス | D20: 犯罪組織
A21: G-020
A22: G-021
A23: G-022
A24: G-023
A25: G-024
A26: G-025

Sheet 懸賞金・肩書ログ
A1: 登場キャラID | B1: 登場キャラ | C1: 懸賞金 | D1: 肩書 | E1: 区分 | F1: 巻数 | G1: 話数 | H1: 年数 | I1: 通算日 | J1: 理由 | K1: 備考
A2: C001-01 | B2: =VLOOKUP(懸賞金・肩書ログ!A2,キャラマスタ[],2,FALSE) -> モンキー・D・ルフィ | D2: 麦わらのルフィ | E2: 海賊 | F2: 1 | G2: 1 | H2: 0 | I2: 1
A3: C001-02 | B3: =VLOOKUP(懸賞金・肩書ログ!A3,キャラマスタ[],2,FALSE) -> ゴール・D・ロジャー | D3: 海賊王 | E3: 海賊 | F3: 1 | G3: 1 | H3: -22 | I3: -8000 | K3: 仮説
A4: C001-05 | B4: =VLOOKUP(懸賞金・肩書ログ!A4,キャラマスタ[],2,FALSE) -> シャンクス | D4: 赤髪のシャンクス | E4: 海賊 | F4: 1 | G4: 1 | H4: -10 | I4: -4015 | K4: 仮説
A5: C001-11 | B5: =VLOOKUP(懸賞金・肩書ログ!A5,キャラマスタ[],2,FALSE) -> ヒグマ | C5: 8000000 | D5: なし | E5: 山賊 | F5: 1 | G5: 1 | H5: -10 | I5: -3650 | J5: 56人殺した | K5: 仮説
A6: C001-17 | B6: =VLOOKUP(懸賞金・肩書ログ!A6,キャラマスタ[],2,FALSE) -> アルビダ | C6: 5000000 | D6: 金棒のアルビダ | E6: 海賊 | F6: 1 | G6: 2 | H6: 0 | I6: 1.3 | K6: 仮説
A7: C001-21 | B7: =VLOOKUP(懸賞金・肩書ログ!A7,キャラマスタ[],2,FALSE) -> ロロノア・ゾロ | D7: 海賊狩りのゾロ | E7: 海賊 | F7: 1 | G7: 3 | H7: 0 | I7: -300 | K7: 仮説
A8: C001-26 | B8: =VLOOKUP(懸賞金・肩書ログ!A8,キャラマスタ[],2,FALSE) -> モーガン | D8: 斧手のモーガン | E8: 海兵 | F8: 1 | G8: 4 | H8: 0 | I8: -1000 | K8: 仮説
A9: C001-34 | B9: =VLOOKUP(懸賞金・肩書ログ!A9,キャラマスタ[],2,FALSE) -> ナミ | D9: 海賊専門泥棒 | E9: 泥棒 | F9: 2 | G9: 9 | H9: 0 | I9: 1.2 | K9: 仮説
A10: C002-01 | B10: =VLOOKUP(懸賞金・肩書ログ!A10,キャラマスタ[],2,FALSE) -> バギー | C10: 15000000 | D10: 道化のバギー | E10: 海賊 | F10: 2 | G10: 9 | H10: 0 | I10: 1.5 | K10: 仮説
A11: C002-04 | B11: =VLOOKUP(懸賞金・肩書ログ!A11,キャラマスタ[],2,FALSE) -> モージ | D11: 猛獣使いのモージ | E11: 海賊 | F11: 2 | G11: 12 | H11: 0 | I11: 1.8 | K11: 仮説
A12: C002-10 | B12: =VLOOKUP(懸賞金・肩書ログ!A12,キャラマスタ[],2,FALSE) -> カバジ | D12: 曲芸のカバジ | E12: 海賊 | F12: 2 | G12: 15 | H12: 0 | I12: 1.8 | K12: 仮説
A13: C003-08 | B13: =VLOOKUP(懸賞金・肩書ログ!A13,キャラマスタ[],2,FALSE) -> クロ | C13: 16000000 | D13: 百計のクロ | E13: 海賊 | F13: 4 | G13: 37 | H13: -3 | I13: -1095 | K13: 仮説
A14: C003-12 | B14: =VLOOKUP(懸賞金・肩書ログ!A14,キャラマスタ[],2,FALSE) -> ジャンゴ | C14: 9000000 | D14: 1・2のジャンゴ | E14: 海賊 | F14: 4 | G14: 28 | H14: 0 | I14: 2.5 | K14: 仮説
A15: C004-01 | B15: =VLOOKUP(懸賞金・肩書ログ!A15,キャラマスタ[],2,FALSE) -> シャム | C15: 3500000 | D15: ニャーバン・兄弟 | E15: 海賊 | F15: 4 | G15: 31 | H15: 0 | I15: 3 | K15: 仮説
A16: C004-02 | B16: =VLOOKUP(懸賞金・肩書ログ!A16,キャラマスタ[],2,FALSE) -> ブチ | C16: 3500000 | D16: ニャーバン・兄弟 | E16: 海賊 | F16: 4 | G16: 31 | H16: 0 | I16: 3 | K16: 仮説
A17: C005-06 | B17: =VLOOKUP(懸賞金・肩書ログ!A17,キャラマスタ[],2,FALSE) -> フルボディ | D17: 鉄拳のフルボディ | E17: 海兵 | F17: 5 | G17: 43 | H17: 0 | I17: 5
A18: C006-03 | B18: =VLOOKUP(懸賞金・肩書ログ!A18,キャラマスタ[],2,FALSE) -> クリーク | C18: 17000000 | D18: 首領・クリーク | E18: 海賊 | F18: 6 | G18: 46 | H18: 0 | I18: -5 | K18: 仮説
A19: C005-10 | B19: =VLOOKUP(懸賞金・肩書ログ!A19,キャラマスタ[],2,FALSE) -> ゼフ | D19: 赫足のゼフ | E19: 元海賊 | F19: 6 | G19: 47 | H19: -9 | I19: -3285 | K19: 仮説
A20: C006-04 | B20: =VLOOKUP(懸賞金・肩書ログ!A20,キャラマスタ[],2,FALSE) -> ジュラキュール・ミホーク | D20: 世界最強の剣士 | E20: 世界政府 | F20: 6 | G20: 51 | H20: 0 | I20: 7 | K20: 仮説
A21: C005-15 | B21: =VLOOKUP(懸賞金・肩書ログ!A21,キャラマスタ[],2,FALSE) -> ギン | C21: 12000000 | D21: 鬼人のギン | E21: 海賊 | F21: 7 | G21: 61 | H21: 0 | I21: -5 | K21: 仮説
A22: C008-05 | B22: =VLOOKUP(懸賞金・肩書ログ!A22,キャラマスタ[],2,FALSE) -> アーロン | C22: 20000000 | D22: ノコギリのアーロン | E22: 海賊 | F22: 8 | G22: 69 | H22: 0 | I22: 8.1 | K22: 仮説
A23: C008-06 | B23: =VLOOKUP(懸賞金・肩書ログ!A23,キャラマスタ[],2,FALSE) -> はっちゃん | C23: 8000000 | D23: 六刀流のハチ | E23: 海賊 | I23: 8.1 | K23: 仮説
A24: C009-04 | B24: =VLOOKUP(懸賞金・肩書ログ!A24,キャラマスタ[],2,FALSE) -> チュウ | C24: 5500000 | E24: 海賊 | F24: 9 | G24: 75 | H24: 0 | I24: 8.5 | K24: 仮説
A25: C009-05 | B25: =VLOOKUP(懸賞金・肩書ログ!A25,キャラマスタ[],2,FALSE) -> クロオビ | C25: 9000000 | E25: 海賊 | F25: 9 | G25: 75 | H25: 0 | I25: 8.5 | K25: 仮説
A26: C001-01 | B26: =VLOOKUP(懸賞金・肩書ログ!A26,キャラマスタ[],2,FALSE) -> モンキー・D・ルフィ | C26: 30000000 | D26: 麦わらのルフィ | E26: 海賊 | F26: 11 | G26: 96 | H26: 0 | I26: 11 | J26: アーロン一味撃破
A27: C013-03 | B27: =VLOOKUP(懸賞金・肩書ログ!A27,キャラマスタ[],2,FALSE) -> ミス・バレンタイン | C27: 7500000 | D27: 運び屋ミキータ | E27: 犯罪組織 | F27: 13 | G27: 110 | H27: 0 | I27: 11.8 | K27: 仮説
A28: C013-02 | B28: =VLOOKUP(懸賞金・肩書ログ!A28,キャラマスタ[],2,FALSE) -> Mr.5 | C28: 10000000 | D28: 国境のジェム | E28: 犯罪組織 | F28: 13 | G28: 110 | H28: 0 | I28: 11.8 | K28: 仮説
B29: =VLOOKUP(懸賞金・肩書ログ!A29,キャラマスタ[],2,FALSE) -> #N/A
B30: =VLOOKUP(懸賞金・肩書ログ!A30,キャラマスタ[],2,FALSE) -> #N/A

Sheet 航海日誌
A1: 日誌ID | B1: 海円暦 | C1: 年（何年前の出来事か） | D1: 通算日 | E1: 巻数 | F1: 話数 | G1: 場所ID | H1: 場所名 | I1: エピソード名 | J1: 出来事 | K1: 登場キャラID | L1: 登場キャラ | M1: 移動手段 | N1: 備考
A2: E001-01 | B2: =1539+C2 -> 1517 | C2: -22 | D2: =C2*365 -> -8030 | E2: 1 | F2: 1 | G2: L-021 | H2: =VLOOKUP(G2,場所マスタ[],6,FALSE) -> ローグタウン | I2: 東の海 | J2: 処刑される | K2: C001-02 | L2: =IFERROR(VLOOKUP(K2,キャラマスタ[],2,FALSE),"") -> ゴール・D・ロジャー | N2: 仮説（場所）
A3: E001-02 | B3: =1539+C3 -> 1528 | C3: -11 | D3: =C3*365 -> -4015 | E3: 1 | F3: 1 | G3: L-001 | H3: =VLOOKUP(G3,場所マスタ[],6,FALSE) -> フーシャ村 | I3: 東の海 | J3: フーシャ村に滞在する | K3: C001-05 | L3: =IFERROR(VLOOKUP(K3,キャラマスタ[],2,FALSE),"") -> シャンクス
A4: E001-03 | B4: =1539+C4 -> 1528 | C4: -11 | D4: =C4*365 -> -4015 | E4: 1 | F4: 1 | G4: L-001 | H4: =VLOOKUP(G4,場所マスタ[],6,FALSE) -> フーシャ村 | I4: 東の海 | J4: フーシャ村に滞在する | K4: C001-06 | L4: =IFERROR(VLOOKUP(K4,キャラマスタ[],2,FALSE),"") -> ラッキー・ルウ
A5: E001-04 | B5: =1539+C5 -> 1528 | C5: -11 | D5: =C5*365 -> -4015 | E5: 1 | F5: 1 | G5: L-001 | H5: =VLOOKUP(G5,場所マスタ[],6,FALSE) -> フーシャ村 | I5: 東の海 | J5: フーシャ村に滞在する | K5: C001-07 | L5: =IFERROR(VLOOKUP(K5,キャラマスタ[],2,FALSE),"") -> ヤソップ
A6: E001-05 | B6: =1539+C6 -> 1528 | C6: -11 | D6: =C6*365 -> -4015 | E6: 1 | F6: 1 | G6: L-001 | H6: =VLOOKUP(G6,場所マスタ[],6,FALSE) -> フーシャ村 | I6: 東の海 | J6: フーシャ村に滞在する | K6: C001-08 | L6: =IFERROR(VLOOKUP(K6,キャラマスタ[],2,FALSE),"") -> ベン・ベックマン
A7: E001-06 | B7: =1539+C7 -> 1529 | C7: -10 | D7: =C7*365 -> -3650 | E7: 1 | F7: 1 | G7: L-001 | H7: =VLOOKUP(G7,場所マスタ[],6,FALSE) -> フーシャ村 | I7: 東の海 | J7: ゴムゴムの実を食べる | K7: C001-01 | L7: =IFERROR(VLOOKUP(K7,キャラマスタ[],2,FALSE),"") -> モンキー・D・ルフィ
A8: E001-07 | B8: =1539+C8 -> 1529 | C8: -10 | D8: -3645 | E8: 1 | F8: 1 | G8: L-002 | H8: =VLOOKUP(G8,場所マスタ[],6,FALSE) -> フーシャ村近海 | I8: 東の海 | J8: 近海の主に食べられる | K8: C001-11 | L8: =IFERROR(VLOOKUP(K8,キャラマスタ[],2,FALSE),"") -> ヒグマ
A9: E001-08 | B9: =1539+C9 -> 1529 | C9: -10 | D9: -3640 | E9: 1 | F9: 1 | G9: L-002 | H9: =VLOOKUP(G9,場所マスタ[],6,FALSE) -> フーシャ村近海 | I9: 東の海 | J9: 近海の主に左腕を食べられる | K9: C001-05 | L9: =IFERROR(VLOOKUP(K9,キャラマスタ[],2,FALSE),"") -> シャンクス
A10: E001-09 | B10: =1539+C10 -> 1529 | C10: -10 | D10: -3640 | E10: 1 | F10: 1 | G10: L-007 | H10: =VLOOKUP(G10,場所マスタ[],6,FALSE) -> 不明 | I10: 東の海 | J10: フーシャ村を出航 | K10: C001-05 | L10: =IFERROR(VLOOKUP(K10,キャラマスタ[],2,FALSE),"") -> シャンクス
A11: E001-10 | B11: =1539+C11 -> 1529 | C11: -10 | D11: -3640 | E11: 1 | F11: 1 | G11: L-007 | H11: =VLOOKUP(G11,場所マスタ[],6,FALSE) -> 不明 | I11: 東の海 | J11: フーシャ村を出航 | K11: C001-06 | L11: =IFERROR(VLOOKUP(K11,キャラマスタ[],2,FALSE),"") -> ラッキー・ルウ
A12: E001-11 | B12: =1539+C12 -> 1529 | C12: -10 | D12: -3640 | E12: 1 | F12: 1 | G12: L-007 | H12: =VLOOKUP(G12,場所マスタ[],6,FALSE) -> 不明 | I12: 東の海 | J12: フーシャ村を出航 | K12: C001-07 | L12: =IFERROR(VLOOKUP(K12,キャラマスタ[],2,FALSE),"") -> ヤソップ
A13: E001-12 | B13: =1539+C13 -> 1529 | C13: -10 | D13: -3640 | E13: 1 | F13: 1 | G13: L-007 | H13: =VLOOKUP(G13,場所マスタ[],6,FALSE) -> 不明 | I13: 東の海 | J13: フーシャ村を出航 | K13: C001-08 | L13: =IFERROR(VLOOKUP(K13,キャラマスタ[],2,FALSE),"") -> ベン・ベックマン
A14: E001-13 | B14: =1539+C14 -> 1539 | C14: 0 | D14: 0 | E14: 1 | F14: 1 | G14: L-001 | H14: =VLOOKUP(G14,場所マスタ[],6,FALSE) -> フーシャ村 | I14: 東の海 | J14: 冒険の夜明け | K14: C001-01 | L14: =IFERROR(VLOOKUP(K14,キャラマスタ[],2,FALSE),"") -> モンキー・D・ルフィ
A15: E001-14 | B15: =1539+C15 -> 1539 | C15: 0 | D15: 1 | E15: 1 | F15: 1 | G15: L-001 | H15: =VLOOKUP(G15,場所マスタ[],6,FALSE) -> フーシャ村 | I15: 東の海 | J15: フーシャ村から出航 | K15: C001-01 | L15: =IFERROR(VLOOKUP(K15,キャラマスタ[],2,FALSE),"") -> モンキー・D・ルフィ | M15: 小舟
A16: E001-15 | B16: =1539+C16 -> 1539 | C16: 0 | D16: 1.1 | E16: 1 | F16: 2 | G16: L-003 | H16: =VLOOKUP(G16,場所マスタ[],6,FALSE) -> ゴート島 | I16: 東の海 | J16: ゴート島に漂着 | K16: C001-01 | L16: =IFERROR(VLOOKUP(K16,キャラマスタ[],2,FALSE),"") -> モンキー・D・ルフィ | M16: 樽
A17: E001-16 | B17: =1539+C17 -> 1537 | C17: -2 | D17: =-2*365 -> -730 | E17: 1 | F17: 2 | G17: L-003 | H17: =VLOOKUP(G17,場所マスタ[],6,FALSE) -> ゴート島 | I17: 東の海 | J17: アルビダの雑用係になる | K17: C001-16 | L17: =IFERROR(VLOOKUP(K17,キャラマスタ[],2,FALSE),"") -> コビー
A18: E001-17 | B18: =1539+C18 -> 1539 | C18: 0 | D18: 1.2 | E18: 1 | F18: 2 | G18: L-003 | H18: =VLOOKUP(G18,場所マスタ[],6,FALSE) -> ゴート島 | I18: 東の海 | J18: アルビダを撃破 | K18: C001-01 | L18: =IFERROR(VLOOKUP(K18,キャラマスタ[],2,FALSE),"") -> モンキー・D・ルフィ
A19: E001-18 | B19: =1539+C19 -> 1539 | C19: 0 | D19: 1.2 | E19: 1 | F19: 2 | G19: L-003 | H19: =VLOOKUP(G19,場所マスタ[],6,FALSE) -> ゴート島 | I19: 東の海 | J19: アルビダを撃破 | K19: C001-17 | L19: =IFERROR(VLOOKUP(K19,キャラマスタ[],2,FALSE),"") -> アルビダ
A20: E001-19 | B20: =1539+C20 -> 1539 | C20: 0 | D20: 1.3 | E20: 1 | F20: 3 | G20: L-004 | H20: =VLOOKUP(G20,場所マスタ[],6,FALSE) -> シェルズタウン | I20: 東の海 | J20: シェルズタウンに到着 | K20: C001-01 | L20: =IFERROR(VLOOKUP(K20,キャラマスタ[],2,FALSE),"") -> モンキー・D・ルフィ | M20: 小舟
A21: E001-20 | B21: =1539+C21 -> 1539 | C21: 0 | D21: 1.3 | E21: 1 | F21: 3 | G21: L-004 | H21: =VLOOKUP(G21,場所マスタ[],6,FALSE) -> シェルズタウン | I21: 東の海 | J21: シェルズタウンに到着 | K21: C001-16 | L21: =IFERROR(VLOOKUP(K21,キャラマスタ[],2,FALSE),"") -> コビー
A22: E001-21 | B22: =1539+C22 -> 1539 | C22: 0 | D22: -7 | E22: 1 | F22: 3 | G22: L-004 | H22: =VLOOKUP(G22,場所マスタ[],6,FALSE) -> シェルズタウン | I22: 東の海 | J22: 磔にされる | K22: C001-21 | L22: =IFERROR(VLOOKUP(K22,キャラマスタ[],2,FALSE),"") -> ロロノア・ゾロ
A23: E001-22 | B23: =1539+C23 -> 1528 | C23: -11 | D23: -4000 | E23: 1 | F23: 5 | G23: L-005 | H23: =VLOOKUP(G23,場所マスタ[],6,FALSE) -> シモツキ村 | I23: 東の海 | J23: くいなが死亡し、ゾロ誓いを立てる | K23: C001-29 | L23: =IFERROR(VLOOKUP(K23,キャラマスタ[],2,FALSE),"") -> くいな
A24: E001-23 | B24: =1539+C24 -> 1528 | C24: -11 | D24: -4000 | E24: 1 | F24: 5 | G24: L-005 | H24: =VLOOKUP(G24,場所マスタ[],6,FALSE) -> シモツキ村 | I24: 東の海 | J24: くいなが死亡し、ゾロ誓いを立てる | K24: C001-21 | L24: =IFERROR(VLOOKUP(K24,キャラマスタ[],2,FALSE),"") -> ロロノア・ゾロ
A25: E001-24 | B25: =1539+C25 -> 1539 | C25: 0 | D25: 1.4 | E25: 1 | F25: 6 | G25: L-004 | H25: =VLOOKUP(G25,場所マスタ[],6,FALSE) -> シェルズタウン | I25: 東の海 | J25: 海軍大佐モーガンを撃破 | K25: C001-01 | L25: =IFERROR(VLOOKUP(K25,キャラマスタ[],2,FALSE),"") -> モンキー・D・ルフィ
A26: E001-25 | B26: =1539+C26 -> 1539 | C26: 0 | D26: 1.4 | E26: 1 | F26: 6 | G26: L-004 | H26: =VLOOKUP(G26,場所マスタ[],6,FALSE) -> シェルズタウン | I26: 東の海 | J26: 海軍大佐モーガンを撃破 | K26: C001-21 | L26: =IFERROR(VLOOKUP(K26,キャラマスタ[],2,FALSE),"") -> ロロノア・ゾロ
A27: E001-26 | B27: =1539+C27 -> 1539 | C27: 0 | D27: 1.4 | E27: 1 | F27: 6 | G27: L-004 | H27: =VLOOKUP(G27,場所マスタ[],6,FALSE) -> シェルズタウン | I27: 東の海 | J27: 海軍大佐モーガンを撃破 | K27: C001-23 | L27: =IFERROR(VLOOKUP(K27,キャラマスタ[],2,FALSE),"") -> ヘルメッポ
A28: E001-27 | B28: =1539+C28 -> 1539 | C28: 0 | D28: 1.4 | E28: 1 | F28: 6 | G28: L-004 | H28: =VLOOKUP(G28,場所マスタ[],6,FALSE) -> シェルズタウン | I28: 東の海 | J28: 海軍大佐モーガンを撃破 | K28: C001-26 | L28: =IFERROR(VLOOKUP(K28,キャラマスタ[],2,FALSE),"") -> モーガン
A29: E001-28 | B29: =1539+C29 -> 1539 | C29: 0 | D29: 1.5 | E29: 1 | F29: 7 | G29: L-004 | H29: =VLOOKUP(G29,場所マスタ[],6,FALSE) -> シェルズタウン | I29: 東の海 | J29: コビーと別れ、出航する | K29: C001-01 | L29: =IFERROR(VLOOKUP(K29,キャラマスタ[],2,FALSE),"") -> モンキー・D・ルフィ
A30: E001-29 | B30: =1539+C30 -> 1539 | C30: 0 | D30: 1.5 | E30: 1 | F30: 7 | G30: L-004 | H30: =VLOOKUP(G30,場所マスタ[],6,FALSE) -> シェルズタウン | I30: 東の海 | J30: コビーと別れ、出航する | K30: C001-21 | L30: =IFERROR(VLOOKUP(K30,キャラマスタ[],2,FALSE),"") -> ロロノア・ゾロ
A31: E001-30 | B31: =1539+C31 -> 1539 | C31: 0 | D31: 1.6 | E31: 1 | F31: 8 | G31: L-006 | H31: =VLOOKUP(G31,場所マスタ[],6,FALSE) -> オレンジの町 | I31: 東の海 | J31: 鳥に運ばれ、町に着く | K31: C001-01 | L31: =IFERROR(VLOOKUP(K31,キャラマスタ[],2,FALSE),"") -> モンキー・D・ルフィ
A32: E001-31 | B32: =1539+C32 -> 1539 | C32: 0 | D32: 1.6 | E32: 1 | F32: 8 | G32: L-008 | H32: =VLOOKUP(G32,場所マスタ[],6,FALSE) -> シェルズタウン近海 | I32: 東の海 | J32: バギーの手下に会う | K32: C001-21 | L32: =IFERROR(VLOOKUP(K32,キャラマスタ[],2,FALSE),"") -> ロロノア・ゾロ
... A73: E001-72 | B73: =1539+C73 -> 1534 | C73: -5 | D73: -1825 | E73: 5 | F73: 40 | G73: L-010 | H73: =VLOOKUP(G73,場所マスタ[],6,FALSE) -> シロップ村 | I73: 東の海 | J73: ウソップ海賊団結成 | K73: C003-03 | L73: =IFERROR(VLOOKUP(K73,キャラマスタ[],2,FALSE),"") -> ウソップ
A74: E001-73 | B74: =1539+C74 -> 1527 | C74: -12 | D74: -4380 | E74: 5 | F74: 41 | G74: L-010 | H74: =VLOOKUP(G74,場所マスタ[],6,FALSE) -> シロップ村 | I74: 東の海 | J74: 村を飛び出し海賊になる | K74: C001-07 | L74: =IFERROR(VLOOKUP(K74,キャラマスタ[],2,FALSE),"") -> ヤソップ | N74: 仮説（年）
A75: E001-74 | B75: =1539+C75 -> 1527 | C75: -12 | D75: -4200 | E75: 5 | F75: 41 | G75: L-010 | H75: =VLOOKUP(G75,場所マスタ[],6,FALSE) -> シロップ村 | I75: 東の海 | J75: 母が病死する | K75: C003-03 | L75: =IFERROR(VLOOKUP(K75,キャラマスタ[],2,FALSE),"") -> ウソップ
A76: E001-75 | B76: =1539+C76 -> 1539 | C76: 0 | D76: 3.3 | E76: 5 | F76: 41 | G76: L-010 | H76: =VLOOKUP(G76,場所マスタ[],6,FALSE) -> シロップ村 | I76: 東の海 | J76: シロップ村を出航 | K76: C001-01 | L76: =IFERROR(VLOOKUP(K76,キャラマスタ[],2,FALSE),"") -> モンキー・D・ルフィ
A77: E001-76 | B77: =1539+C77 -> 1539 | C77: 0 | D77: 3.3 | E77: 5 | F77: 41 | G77: L-010 | H77: =VLOOKUP(G77,場所マスタ[],6,FALSE) -> シロップ村 | I77: 東の海 | J77: シロップ村を出航 | K77: C001-21 | L77: =IFERROR(VLOOKUP(K77,キャラマスタ[],2,FALSE),"") -> ロロノア・ゾロ
A78: E001-77 | B78: =1539+C78 -> 1539 | C78: 0 | D78: 3.3 | E78: 5 | F78: 41 | G78: L-010 | H78: =VLOOKUP(G78,場所マスタ[],6,FALSE) -> シロップ村 | I78: 東の海 | J78: シロップ村を出航 | K78: C001-34 | L78: =IFERROR(VLOOKUP(K78,キャラマスタ[],2,FALSE),"") -> ナミ
A79: E001-78 | B79: =1539+C79 -> 1539 | C79: 0 | D79: 3.3 | E79: 5 | F79: 41 | G79: L-010 | H79: =VLOOKUP(G79,場所マスタ[],6,FALSE) -> シロップ村 | I79: 東の海 | J79: シロップ村を出航 | K79: C003-03 | L79: =IFERROR(VLOOKUP(K79,キャラマスタ[],2,FALSE),"") -> ウソップ
A80: E001-79 | B80: =1539+C80 -> 1539 | C80: 0 | D80: 3.5 | E80: 5 | F80: 42 | G80: L-012 | H80: =VLOOKUP(G80,場所マスタ[],6,FALSE) -> シロップ村近海 | I80: 東の海 | J80: ヨサクとジョニーと出会う | K80: C001-01 | L80: =IFERROR(VLOOKUP(K80,キャラマスタ[],2,FALSE),"") -> モンキー・D・ルフィ
...

Sheet 戦闘ログ
A1: バトルID | B1: 巻数 | C1: 話数 | D1: 年 | E1: 通算日 | F1: 場所ID | G1: 場所 | H1: 勢力ID1 | I1: 勝者勢力 | J1: 勝者ID1 | K1: 勝者ID2 | L1: 勝者1 | M1: 勝者2 | N1: 勢力ID2 | O1: 敗者勢力 | P1: 敗者ID1 | Q1: 敗者ID2 | R1: 敗者1 | S1: 敗者2 | T1: 技ID | U1: 決まり手 | V1: バトルの種類 | W1: 軍団戦フラグ
A2: B001-01 | B2: 1 | C2: 1 | D2: -10 | E2: -3645 | F2: L-001 | G2: =VLOOKUP(F2,場所マスタ!$A$1:$I$125,5,FALSE) -> フーシャ村 | H2: G-003 | I2: =IFERROR(VLOOKUP(H2,勢力マスタ[],2,FALSE),"") -> 赤髪海賊団 | L2: =IFERROR(VLOOKUP(J2,キャラマスタ[],2,FALSE),"") | M2: =IFERROR(VLOOKUP(K2,キャラマスタ[],2,FALSE),"") | N2: G-004 | O2: =IFERROR(VLOOKUP(N2,勢力マスタ[],2,FALSE),"") -> ヒグマ山賊団 | R2: =IFERROR(VLOOKUP(P2,キャラマスタ[],2,FALSE),"") | S2: =IFERROR(VLOOKUP(Q2,キャラマスタ[],2,FALSE),"") | U2: =+IFERROR(VLOOKUP(テーブル10[[#This Row],[技ID]],技マスタ[],2,FALSE),"") | V2: 軍団戦 | W2: 1
A3: B001-02 | B3: 1 | C3: 1 | D3: -10 | E3: 1 | F3: L-002 | G3: =VLOOKUP(F3,場所マスタ!$A$1:$I$125,5,FALSE) -> フーシャ村近海 | I3: =IFERROR(VLOOKUP(H3,勢力マスタ[],2,FALSE),"") | J3: C001-01 | L3: =IFERROR(VLOOKUP(J3,キャラマスタ[],2,FALSE),"") -> モンキー・D・ルフィ | M3: =IFERROR(VLOOKUP(K3,キャラマスタ[],2,FALSE),"") | O3: =IFERROR(VLOOKUP(N3,勢力マスタ[],2,FALSE),"") | P3: C001-15 | R3: =IFERROR(VLOOKUP(P3,キャラマスタ[],2,FALSE),"") -> 近海の主 | S3: =IFERROR(VLOOKUP(Q3,キャラマスタ[],2,FALSE),"") | T3: M-001 | U3: =+IFERROR(VLOOKUP(テーブル10[[#This Row],[技ID]],技マスタ[],2,FALSE),"") -> ゴムゴムの銃（ピストル） | V3: タイマン
A4: B001-03 | B4: 1 | C4: 2 | D4: 0 | E4: 1.2 | F4: L-003 | G4: =VLOOKUP(F4,場所マスタ!$A$1:$I$125,5,FALSE) -> （不明） | I4: =IFERROR(VLOOKUP(H4,勢力マスタ[],2,FALSE),"") | J4: C001-01 | L4: =IFERROR(VLOOKUP(J4,キャラマスタ[],2,FALSE),"") -> モンキー・D・ルフィ | M4: =IFERROR(VLOOKUP(K4,キャラマスタ[],2,FALSE),"") | O4: =IFERROR(VLOOKUP(N4,勢力マスタ[],2,FALSE),"") | P4: C001-17 | R4: =IFERROR(VLOOKUP(P4,キャラマスタ[],2,FALSE),"") -> アルビダ | S4: =IFERROR(VLOOKUP(Q4,キャラマスタ[],2,FALSE),"") | T4: M-001 | U4: =+IFERROR(VLOOKUP(テーブル10[[#This Row],[技ID]],技マスタ[],2,FALSE),"") -> ゴムゴムの銃（ピストル） | V4: タイマン
A5: B001-04 | B5: 1 | C5: 5 | D5: -9 | E5: -4000 | F5: L-005 | G5: =VLOOKUP(F5,場所マスタ!$A$1:$I$125,5,FALSE) -> シモツキ村 | I5: =IFERROR(VLOOKUP(H5,勢力マスタ[],2,FALSE),"") | J5: C001-29 | L5: =IFERROR(VLOOKUP(J5,キャラマスタ[],2,FALSE),"") -> くいな | M5: =IFERROR(VLOOKUP(K5,キャラマスタ[],2,FALSE),"") | O5: =IFERROR(VLOOKUP(N5,勢力マスタ[],2,FALSE),"") | P5: C001-21 | R5: =IFERROR(VLOOKUP(P5,キャラマスタ[],2,FALSE),"") -> ロロノア・ゾロ | S5: =IFERROR(VLOOKUP(Q5,キャラマスタ[],2,FALSE),"") | U5: =+IFERROR(VLOOKUP(テーブル10[[#This Row],[技ID]],技マスタ[],2,FALSE),"") | V5: タイマン
A6: B001-05 | B6: 1 | C6: 6 | D6: 0 | E6: 1.4 | F6: L-004 | G6: =VLOOKUP(F6,場所マスタ!$A$1:$I$125,5,FALSE) -> シェルズタウン | I6: =IFERROR(VLOOKUP(H6,勢力マスタ[],2,FALSE),"") | J6: C001-01 | K6: C001-21 | L6: =IFERROR(VLOOKUP(J6,キャラマスタ[],2,FALSE),"") -> モンキー・D・ルフィ | M6: =IFERROR(VLOOKUP(K6,キャラマスタ[],2,FALSE),"") -> ロロノア・ゾロ | O6: =IFERROR(VLOOKUP(N6,勢力マスタ[],2,FALSE),"") | P6: C001-26 | Q6: C001-23 | R6: =IFERROR(VLOOKUP(P6,キャラマスタ[],2,FALSE),"") -> モーガン | S6: =IFERROR(VLOOKUP(Q6,キャラマスタ[],2,FALSE),"") -> ヘルメッポ | T6: M-001 | U6: =+IFERROR(VLOOKUP(テーブル10[[#This Row],[技ID]],技マスタ[],2,FALSE),"") -> ゴムゴムの銃（ピストル） | V6: チーム戦
A7: B001-06 | B7: 2 | C7: 10 | D7: 0 | E7: 1.7 | F7: L-006 | G7: =VLOOKUP(F7,場所マスタ!$A$1:$I$125,5,FALSE) -> オレンジの町 | I7: =IFERROR(VLOOKUP(H7,勢力マスタ[],2,FALSE),"") | J7: C002-01 | L7: =IFERROR(VLOOKUP(J7,キャラマスタ[],2,FALSE),"") -> バギー | M7: =IFERROR(VLOOKUP(K7,キャラマスタ[],2,FALSE),"") | O7: =IFERROR(VLOOKUP(N7,勢力マスタ[],2,FALSE),"") | P7: C001-21 | R7: =IFERROR(VLOOKUP(P7,キャラマスタ[],2,FALSE),"") -> ロロノア・ゾロ | S7: =IFERROR(VLOOKUP(Q7,キャラマスタ[],2,FALSE),"") | U7: =+IFERROR(VLOOKUP(テーブル10[[#This Row],[技ID]],技マスタ[],2,FALSE),"") | V7: タイマン
A8: B001-07 | B8: 2 | C8: 12 | D8: 0 | E8: 1.8 | F8: L-006 | G8: =VLOOKUP(F8,場所マスタ!$A$1:$I$125,5,FALSE) -> オレンジの町 | H8: G-001 | I8: =IFERROR(VLOOKUP(H8,勢力マスタ[],2,FALSE),"") -> 麦わらの一味 | J8: C001-01 | L8: =IFERROR(VLOOKUP(J8,キャラマスタ[],2,FALSE),"") -> モンキー・D・ルフィ | M8: =IFERROR(VLOOKUP(K8,キャラマスタ[],2,FALSE),"") | N8: G-009 | O8: =IFERROR(VLOOKUP(N8,勢力マスタ[],2,FALSE),"") -> バギー海賊団 | P8: C002-04 | Q8: C002-05 | R8: =IFERROR(VLOOKUP(P8,キャラマスタ[],2,FALSE),"") -> モージ | S8: =IFERROR(VLOOKUP(Q8,キャラマスタ[],2,FALSE),"") -> リッチー | T8: M-006 | U8: =+IFERROR(VLOOKUP(テーブル10[[#This Row],[技ID]],技マスタ[],2,FALSE),"") -> ゴムゴムの槌（ツチ） | V8: タイマン
A9: B001-08 | B9: 2 | C9: 16 | D9: 0 | E9: 1.8 | F9: L-006 | G9: =VLOOKUP(F9,場所マスタ!$A$1:$I$125,5,FALSE) -> オレンジの町 | H9: G-001 | I9: =IFERROR(VLOOKUP(H9,勢力マスタ[],2,FALSE),"") -> 麦わらの一味 | J9: C001-21 | L9: =IFERROR(VLOOKUP(J9,キャラマスタ[],2,FALSE),"") -> ロロノア・ゾロ | M9: =IFERROR(VLOOKUP(K9,キャラマスタ[],2,FALSE),"") | N9: G-009 | O9: =IFERROR(VLOOKUP(N9,勢力マスタ[],2,FALSE),"") -> バギー海賊団 | P9: C002-10 | R9: =IFERROR(VLOOKUP(P9,キャラマスタ[],2,FALSE),"") -> カバジ | S9: =IFERROR(VLOOKUP(Q9,キャラマスタ[],2,FALSE),"") | T9: M-015 | U9: =+IFERROR(VLOOKUP(テーブル10[[#This Row],[技ID]],技マスタ[],2,FALSE),"") -> 鬼斬り | V9: タイマン
A10: B001-09 | B10: 3 | C10: 18 | D10: 0 | E10: 1.8 | F10: L-006 | G10: =VLOOKUP(F10,場所マスタ!$A$1:$I$125,5,FALSE) -> オレンジの町 | H10: G-001 | I10: =IFERROR(VLOOKUP(H10,勢力マスタ[],2,FALSE),"") -> 麦わらの一味 | J10: C001-01 | L10: =IFERROR(VLOOKUP(J10,キャラマスタ[],2,FALSE),"") -> モンキー・D・ルフィ | M10: =IFERROR(VLOOKUP(K10,キャラマスタ[],2,FALSE),"") | N10: G-009 | O10: =IFERROR(VLOOKUP(N10,勢力マスタ[],2,FALSE),"") -> バギー海賊団 | P10: C002-01 | R10: =IFERROR(VLOOKUP(P10,キャラマスタ[],2,FALSE),"") -> バギー | S10: =IFERROR(VLOOKUP(Q10,キャラマスタ[],2,FALSE),"") | T10: M-021 | U10: =+IFERROR(VLOOKUP(テーブル10[[#This Row],[技ID]],技マスタ[],2,FALSE),"") -> ゴムゴムのバズーカ | V10: タイマン
A11: B001-10 | B11: 4 | C11: 31 | D11: 0 | E11: 3 | F11: L-010 | G11: =VLOOKUP(F11,場所マスタ!$A$1:$I$125,5,FALSE) -> シロップ村 | H11: G-001 | I11: =IFERROR(VLOOKUP(H11,勢力マスタ[],2,FALSE),"") -> 麦わらの一味 | J11: C001-21 | L11: =IFERROR(VLOOKUP(J11,キャラマスタ[],2,FALSE),"") -> ロロノア・ゾロ | M11: =IFERROR(VLOOKUP(K11,キャラマスタ[],2,FALSE),"") | N11: G-011 | O11: =IFERROR(VLOOKUP(N11,勢力マスタ[],2,FALSE),"") -> クロネコ海賊団 | P11: C004-01 | Q11: C004-02 | R11: =IFERROR(VLOOKUP(P11,キャラマスタ[],2,FALSE),"") -> シャム | S11: =IFERROR(VLOOKUP(Q11,キャラマスタ[],2,FALSE),"") -> ブチ | T11: M-030 | U11: =+IFERROR(VLOOKUP(テーブル10[[#This Row],[技ID]],技マスタ[],2,FALSE),"") -> 虎狩り | V11: タイマン
A12: B001-11 | B12: 4 | C12: 34 | D12: 0 | E12: 3 | F12: L-010 | G12: =VLOOKUP(F12,場所マスタ!$A$1:$I$125,5,FALSE) -> シロップ村 | H12: G-001 | I12: =IFERROR(VLOOKUP(H12,勢力マスタ[],2,FALSE),"") -> 麦わらの一味 | J12: C001-01 | L12: =IFERROR(VLOOKUP(J12,キャラマスタ[],2,FALSE),"") -> モンキー・D・ルフィ | M12: =IFERROR(VLOOKUP(K12,キャラマスタ[],2,FALSE),"") | N12: G-011 | O12: =IFERROR(VLOOKUP(N12,勢力マスタ[],2,FALSE),"") -> クロネコ海賊団 | P12: C003-08 | R12: =IFERROR(VLOOKUP(P12,キャラマスタ[],2,FALSE),"") -> クロ | S12: =IFERROR(VLOOKUP(Q12,キャラマスタ[],2,FALSE),"") | T12: M-035 | U12: =+IFERROR(VLOOKUP(テーブル10[[#This Row],[技ID]],技マスタ[],2,FALSE),"") -> ゴムゴムの鐘（カネ） | V12: タイマン
A13: B001-12 | B13: 5 | C13: 38 | D13: 0 | E13: 3 | F13: L-010 | G13: =VLOOKUP(F13,場所マスタ!$A$1:$I$125,5,FALSE) -> シロップ村 | H13: G-001 | I13: =IFERROR(VLOOKUP(H13,勢力マスタ[],2,FALSE),"") -> 麦わらの一味 | J13: C001-21 | K13: C003-03 | L13: =IFERROR(VLOOKUP(J13,キャラマスタ[],2,FALSE),"") -> ロロノア・ゾロ | M13: =IFERROR(VLOOKUP(K13,キャラマスタ[],2,FALSE),"") -> ウソップ | N13: G-011 | O13: =IFERROR(VLOOKUP(N13,勢力マスタ[],2,FALSE),"") -> クロネコ海賊団 | P13: C003-12 | R13: =IFERROR(VLOOKUP(P13,キャラマスタ[],2,FALSE),"") -> ジャンゴ | S13: =IFERROR(VLOOKUP(Q13,キャラマスタ[],2,FALSE),"") | T13: M-034 | U13: =+IFERROR(VLOOKUP(テーブル10[[#This Row],[技ID]],技マスタ[],2,FALSE),"") -> 火薬星 | V13: チーム戦
A14: B001-13 | B14: 5 | C14: 43 | D14: 0 | E14: 5 | F14: L-013 | G14: =VLOOKUP(F14,場所マスタ!$A$1:$I$125,5,FALSE) -> バラティエ | I14: =IFERROR(VLOOKUP(H14,勢力マスタ[],2,FALSE),"") | J14: C005-06 | L14: =IFERROR(VLOOKUP(J14,キャラマスタ[],2,FALSE),"") -> フルボディ | M14: =IFERROR(VLOOKUP(K14,キャラマスタ[],2,FALSE),"") | O14: =IFERROR(VLOOKUP(N14,勢力マスタ[],2,FALSE),"") | P14: C005-04 | Q14: C005-05 | R14: =IFERROR(VLOOKUP(P14,キャラマスタ[],2,FALSE),"") -> ヨサク | S14: =IFERROR(VLOOKUP(Q14,キャラマスタ[],2,FALSE),"") -> ジョニー | U14: =+IFERROR(VLOOKUP(テーブル10[[#This Row],[技ID]],技マスタ[],2,FALSE),"") | V14: タイマン
A15: B001-14 | B15: 5 | C15: 43 | D15: 0 | E15: 5 | F15: L-013 | G15: =VLOOKUP(F15,場所マスタ!$A$1:$I$125,5,FALSE) -> バラティエ | H15: G-012 | I15: =IFERROR(VLOOKUP(H15,勢力マスタ[],2,FALSE),"") -> 海上レストランバラティエ | J15: C005-09 | L15: =IFERROR(VLOOKUP(J15,キャラマスタ[],2,FALSE),"") -> サンジ | M15: =IFERROR(VLOOKUP(K15,キャラマスタ[],2,FALSE),"") | O15: =IFERROR(VLOOKUP(N15,勢力マスタ[],2,FALSE),"") | P15: C005-06 | R15: =IFERROR(VLOOKUP(P15,キャラマスタ[],2,FALSE),"") -> フルボディ | S15: =IFERROR(VLOOKUP(Q15,キャラマスタ[],2,FALSE),"") | U15: =+IFERROR(VLOOKUP(テーブル10[[#This Row],[技ID]],技マスタ[],2,FALSE),"") | V15: タイマン
A16: B001-15 | B16: 5 | C16: 44 | D16: 0 | E16: 5 | F16: L-013 | G16: =VLOOKUP(F16,場所マスタ!$A$1:$I$125,5,FALSE) -> バラティエ | H16: G-012 | I16: =IFERROR(VLOOKUP(H16,勢力マスタ[],2,FALSE),"") -> 海上レストランバラティエ | J16: C005-12 | L16: =IFERROR(VLOOKUP(J16,キャラマスタ[],2,FALSE),"") -> パティ | M16: =IFERROR(VLOOKUP(K16,キャラマスタ[],2,FALSE),"") | N16: G-013 | O16: =IFERROR(VLOOKUP(N16,勢力マスタ[],2,FALSE),"") -> クリーク海賊団 | P16: C005-15 | R16: =IFERROR(VLOOKUP(P16,キャラマスタ[],2,FALSE),"") -> ギン | S16: =IFERROR(VLOOKUP(Q16,キャラマスタ[],2,FALSE),"") | U16: =+IFERROR(VLOOKUP(テーブル10[[#This Row],[技ID]],技マスタ[],2,FALSE),"") | V16: タイマン
